
Internal Server Error: /options/262/
Traceback (most recent call last):
  File "/usr/local/lib/python3.5/dist-packages/django/core/handlers/base.py", line 149, in get_response
    response = self.process_exception_by_middleware(e, request)
  File "/usr/local/lib/python3.5/dist-packages/django/core/handlers/base.py", line 147, in get_response
    response = wrapped_callback(request, *callback_args, **callback_kwargs)
  File "/opt/WebWord2Vec/WV/views.py", line 250, in Enteroptions
    int(request.POST['minc'])))
  File "/opt/WebWord2Vec/WV/views.py", line 245, in Map
    BuildHtmlMap()
  File "/opt/WebWord2Vec/WV/views.py", line 216, in BuildHtmlMap
    export_png(p1,os.path.join(STATICFILES_DIRS[0],picture_name))
  File "/usr/local/lib/python3.5/dist-packages/bokeh/io.py", line 666, in export_png
    image = _get_screenshot_as_png(obj)
  File "/usr/local/lib/python3.5/dist-packages/bokeh/io.py", line 623, in _get_screenshot_as_png
    driver = webdriver.PhantomJS()
  File "/usr/local/lib/python3.5/dist-packages/selenium/webdriver/phantomjs/webdriver.py", line 52, in __init__
    self.service.start()
  File "/usr/local/lib/python3.5/dist-packages/selenium/webdriver/common/service.py", line 96, in start
    self.assert_process_still_running()
  File "/usr/local/lib/python3.5/dist-packages/selenium/webdriver/common/service.py", line 109, in assert_process_still_running
    % (self.path, return_code)
selenium.common.exceptions.WebDriverException: Message: Service phantomjs unexpectedly exited. Status code was: -6

Internal Server Error: /options/262/
Traceback (most recent call last):
  File "/usr/local/lib/python3.5/dist-packages/django/core/handlers/base.py", line 149, in get_response
    response = self.process_exception_by_middleware(e, request)
  File "/usr/local/lib/python3.5/dist-packages/django/core/handlers/base.py", line 147, in get_response
    response = wrapped_callback(request, *callback_args, **callback_kwargs)
  File "/opt/WebWord2Vec/WV/views.py", line 250, in Enteroptions
    int(request.POST['minc'])))
  File "/opt/WebWord2Vec/WV/views.py", line 245, in Map
    BuildHtmlMap()
  File "/opt/WebWord2Vec/WV/views.py", line 216, in BuildHtmlMap
    export_png(p1,os.path.join(STATICFILES_DIRS[0],picture_name))
  File "/usr/local/lib/python3.5/dist-packages/bokeh/io.py", line 666, in export_png
    image = _get_screenshot_as_png(obj)
  File "/usr/local/lib/python3.5/dist-packages/bokeh/io.py", line 623, in _get_screenshot_as_png
    driver = webdriver.PhantomJS()
  File "/usr/local/lib/python3.5/dist-packages/selenium/webdriver/phantomjs/webdriver.py", line 52, in __init__
    self.service.start()
  File "/usr/local/lib/python3.5/dist-packages/selenium/webdriver/common/service.py", line 96, in start
    self.assert_process_still_running()
  File "/usr/local/lib/python3.5/dist-packages/selenium/webdriver/common/service.py", line 109, in assert_process_still_running
    % (self.path, return_code)
selenium.common.exceptions.WebDriverException: Message: Service phantomjs unexpectedly exited. Status code was: -6

Internal Server Error: /options/262/
Traceback (most recent call last):
  File "/usr/local/lib/python3.5/dist-packages/django/core/handlers/base.py", line 149, in get_response
    response = self.process_exception_by_middleware(e, request)
  File "/usr/local/lib/python3.5/dist-packages/django/core/handlers/base.py", line 147, in get_response
    response = wrapped_callback(request, *callback_args, **callback_kwargs)
  File "/opt/WebWord2Vec/WV/views.py", line 250, in Enteroptions
    int(request.POST['minc'])))
  File "/opt/WebWord2Vec/WV/views.py", line 245, in Map
    BuildHtmlMap()
  File "/opt/WebWord2Vec/WV/views.py", line 216, in BuildHtmlMap
    export_png(p1,os.path.join(STATICFILES_DIRS[0],picture_name))
  File "/usr/local/lib/python3.5/dist-packages/bokeh/io.py", line 666, in export_png
    image = _get_screenshot_as_png(obj)
  File "/usr/local/lib/python3.5/dist-packages/bokeh/io.py", line 623, in _get_screenshot_as_png
    driver = webdriver.PhantomJS()
  File "/usr/local/lib/python3.5/dist-packages/selenium/webdriver/phantomjs/webdriver.py", line 52, in __init__
    self.service.start()
  File "/usr/local/lib/python3.5/dist-packages/selenium/webdriver/common/service.py", line 96, in start
    self.assert_process_still_running()
  File "/usr/local/lib/python3.5/dist-packages/selenium/webdriver/common/service.py", line 109, in assert_process_still_running
    % (self.path, return_code)
selenium.common.exceptions.WebDriverException: Message: Service phantomjs unexpectedly exited. Status code was: -6

Internal Server Error: /options/262/
Traceback (most recent call last):
  File "/usr/local/lib/python3.5/dist-packages/django/core/handlers/base.py", line 149, in get_response
    response = self.process_exception_by_middleware(e, request)
  File "/usr/local/lib/python3.5/dist-packages/django/core/handlers/base.py", line 147, in get_response
    response = wrapped_callback(request, *callback_args, **callback_kwargs)
  File "/opt/WebWord2Vec/WV/views.py", line 250, in Enteroptions
    int(request.POST['minc'])))
  File "/opt/WebWord2Vec/WV/views.py", line 245, in Map
    BuildHtmlMap()
  File "/opt/WebWord2Vec/WV/views.py", line 216, in BuildHtmlMap
    export_png(p1,os.path.join(STATICFILES_DIRS[0],picture_name))
  File "/usr/local/lib/python3.5/dist-packages/bokeh/io.py", line 666, in export_png
    image = _get_screenshot_as_png(obj)
  File "/usr/local/lib/python3.5/dist-packages/bokeh/io.py", line 623, in _get_screenshot_as_png
    driver = webdriver.PhantomJS()
  File "/usr/local/lib/python3.5/dist-packages/selenium/webdriver/phantomjs/webdriver.py", line 52, in __init__
    self.service.start()
  File "/usr/local/lib/python3.5/dist-packages/selenium/webdriver/common/service.py", line 96, in start
    self.assert_process_still_running()
  File "/usr/local/lib/python3.5/dist-packages/selenium/webdriver/common/service.py", line 109, in assert_process_still_running
    % (self.path, return_code)
selenium.common.exceptions.WebDriverException: Message: Service phantomjs unexpectedly exited. Status code was: -6

Internal Server Error: /options/262/
Traceback (most recent call last):
  File "/usr/local/lib/python3.5/dist-packages/bokeh/util/dependencies.py", line 62, in detect_phantomjs
    proc = Popen([phantomjs_path, "--version"], stdout=PIPE, stderr=PIPE)
  File "/usr/lib/python3.5/subprocess.py", line 947, in __init__
    restore_signals, start_new_session)
  File "/usr/lib/python3.5/subprocess.py", line 1551, in _execute_child
    raise child_exception_type(errno_num, err_msg)
FileNotFoundError: [Errno 2] No such file or directory: 'phantomjs'

During handling of the above exception, another exception occurred:

Traceback (most recent call last):
  File "/usr/local/lib/python3.5/dist-packages/django/core/handlers/base.py", line 149, in get_response
    response = self.process_exception_by_middleware(e, request)
  File "/usr/local/lib/python3.5/dist-packages/django/core/handlers/base.py", line 147, in get_response
    response = wrapped_callback(request, *callback_args, **callback_kwargs)
  File "/opt/WebWord2Vec/WV/views.py", line 250, in Enteroptions
    int(request.POST['minc'])))
  File "/opt/WebWord2Vec/WV/views.py", line 245, in Map
    BuildHtmlMap()
  File "/opt/WebWord2Vec/WV/views.py", line 216, in BuildHtmlMap
    export_png(p1,os.path.join(STATICFILES_DIRS[0],picture_name))
  File "/usr/local/lib/python3.5/dist-packages/bokeh/io.py", line 666, in export_png
    image = _get_screenshot_as_png(obj)
  File "/usr/local/lib/python3.5/dist-packages/bokeh/io.py", line 618, in _get_screenshot_as_png
    detect_phantomjs()
  File "/usr/local/lib/python3.5/dist-packages/bokeh/util/dependencies.py", line 66, in detect_phantomjs
    "npm install -g phantomjs-prebuilt"')
RuntimeError: PhantomJS is not present in PATH. Try "conda install phantomjs" or                            "npm install -g phantomjs-prebuilt"
Internal Server Error: /
Traceback (most recent call last):
  File "/usr/local/lib/python3.5/dist-packages/django/core/handlers/base.py", line 149, in get_response
    response = self.process_exception_by_middleware(e, request)
  File "/usr/local/lib/python3.5/dist-packages/django/core/handlers/base.py", line 147, in get_response
    response = wrapped_callback(request, *callback_args, **callback_kwargs)
  File "/opt/WebWord2Vec/WV/views.py", line 61, in MainPage
    tg=Tags(text_id=Data.objects.get(Data_xls=request.FILES['Data_xls']).pk,tg=i)
  File "/usr/local/lib/python3.5/dist-packages/django/db/models/manager.py", line 122, in manager_method
    return getattr(self.get_queryset(), name)(*args, **kwargs)
  File "/usr/local/lib/python3.5/dist-packages/django/db/models/query.py", line 387, in get
    self.model._meta.object_name
WV.models.DoesNotExist: Data matching query does not exist.
Internal Server Error: /
Traceback (most recent call last):
  File "/usr/local/lib/python3.5/dist-packages/django/core/handlers/base.py", line 134, in get_response
    resolver_match = resolver.resolve(request.path_info)
  File "/usr/local/lib/python3.5/dist-packages/django/core/urlresolvers.py", line 374, in resolve
    for pattern in self.url_patterns:
  File "/usr/local/lib/python3.5/dist-packages/django/utils/functional.py", line 33, in __get__
    res = instance.__dict__[self.name] = self.func(instance)
  File "/usr/local/lib/python3.5/dist-packages/django/core/urlresolvers.py", line 417, in url_patterns
    patterns = getattr(self.urlconf_module, "urlpatterns", self.urlconf_module)
  File "/usr/local/lib/python3.5/dist-packages/django/utils/functional.py", line 33, in __get__
    res = instance.__dict__[self.name] = self.func(instance)
  File "/usr/local/lib/python3.5/dist-packages/django/core/urlresolvers.py", line 410, in urlconf_module
    return import_module(self.urlconf_name)
  File "/usr/lib/python3.5/importlib/__init__.py", line 126, in import_module
    return _bootstrap._gcd_import(name[level:], package, level)
  File "<frozen importlib._bootstrap>", line 986, in _gcd_import
  File "<frozen importlib._bootstrap>", line 969, in _find_and_load
  File "<frozen importlib._bootstrap>", line 958, in _find_and_load_unlocked
  File "<frozen importlib._bootstrap>", line 673, in _load_unlocked
  File "<frozen importlib._bootstrap_external>", line 665, in exec_module
  File "<frozen importlib._bootstrap>", line 222, in _call_with_frames_removed
  File "/opt/WebWord2Vec/Word2Vec/urls.py", line 23, in <module>
    url(r'^', include('WV.urls')),
  File "/usr/local/lib/python3.5/dist-packages/django/conf/urls/__init__.py", line 52, in include
    urlconf_module = import_module(urlconf_module)
  File "/usr/lib/python3.5/importlib/__init__.py", line 126, in import_module
    return _bootstrap._gcd_import(name[level:], package, level)
  File "<frozen importlib._bootstrap>", line 986, in _gcd_import
  File "<frozen importlib._bootstrap>", line 969, in _find_and_load
  File "<frozen importlib._bootstrap>", line 958, in _find_and_load_unlocked
  File "<frozen importlib._bootstrap>", line 673, in _load_unlocked
  File "<frozen importlib._bootstrap_external>", line 665, in exec_module
  File "<frozen importlib._bootstrap>", line 222, in _call_with_frames_removed
  File "/opt/WebWord2Vec/WV/urls.py", line 2, in <module>
    from WV import views
  File "/opt/WebWord2Vec/WV/views.py", line 59
    print(request.FILES['Data_xls']).id)
                                        ^
TabError: inconsistent use of tabs and spaces in indentation
Internal Server Error: /
Traceback (most recent call last):
  File "/usr/local/lib/python3.5/dist-packages/django/core/handlers/base.py", line 134, in get_response
    resolver_match = resolver.resolve(request.path_info)
  File "/usr/local/lib/python3.5/dist-packages/django/core/urlresolvers.py", line 374, in resolve
    for pattern in self.url_patterns:
  File "/usr/local/lib/python3.5/dist-packages/django/utils/functional.py", line 33, in __get__
    res = instance.__dict__[self.name] = self.func(instance)
  File "/usr/local/lib/python3.5/dist-packages/django/core/urlresolvers.py", line 417, in url_patterns
    patterns = getattr(self.urlconf_module, "urlpatterns", self.urlconf_module)
  File "/usr/local/lib/python3.5/dist-packages/django/utils/functional.py", line 33, in __get__
    res = instance.__dict__[self.name] = self.func(instance)
  File "/usr/local/lib/python3.5/dist-packages/django/core/urlresolvers.py", line 410, in urlconf_module
    return import_module(self.urlconf_name)
  File "/usr/lib/python3.5/importlib/__init__.py", line 126, in import_module
    return _bootstrap._gcd_import(name[level:], package, level)
  File "<frozen importlib._bootstrap>", line 986, in _gcd_import
  File "<frozen importlib._bootstrap>", line 969, in _find_and_load
  File "<frozen importlib._bootstrap>", line 958, in _find_and_load_unlocked
  File "<frozen importlib._bootstrap>", line 673, in _load_unlocked
  File "<frozen importlib._bootstrap_external>", line 665, in exec_module
  File "<frozen importlib._bootstrap>", line 222, in _call_with_frames_removed
  File "/opt/WebWord2Vec/Word2Vec/urls.py", line 23, in <module>
    url(r'^', include('WV.urls')),
  File "/usr/local/lib/python3.5/dist-packages/django/conf/urls/__init__.py", line 52, in include
    urlconf_module = import_module(urlconf_module)
  File "/usr/lib/python3.5/importlib/__init__.py", line 126, in import_module
    return _bootstrap._gcd_import(name[level:], package, level)
  File "<frozen importlib._bootstrap>", line 986, in _gcd_import
  File "<frozen importlib._bootstrap>", line 969, in _find_and_load
  File "<frozen importlib._bootstrap>", line 958, in _find_and_load_unlocked
  File "<frozen importlib._bootstrap>", line 673, in _load_unlocked
  File "<frozen importlib._bootstrap_external>", line 665, in exec_module
  File "<frozen importlib._bootstrap>", line 222, in _call_with_frames_removed
  File "/opt/WebWord2Vec/WV/urls.py", line 2, in <module>
    from WV import views
  File "/opt/WebWord2Vec/WV/views.py", line 59
    print(request.FILES['Data_xls'].id)
                                       ^
TabError: inconsistent use of tabs and spaces in indentation
Internal Server Error: /
Traceback (most recent call last):
  File "/usr/local/lib/python3.5/dist-packages/django/core/handlers/base.py", line 134, in get_response
    resolver_match = resolver.resolve(request.path_info)
  File "/usr/local/lib/python3.5/dist-packages/django/core/urlresolvers.py", line 374, in resolve
    for pattern in self.url_patterns:
  File "/usr/local/lib/python3.5/dist-packages/django/utils/functional.py", line 33, in __get__
    res = instance.__dict__[self.name] = self.func(instance)
  File "/usr/local/lib/python3.5/dist-packages/django/core/urlresolvers.py", line 417, in url_patterns
    patterns = getattr(self.urlconf_module, "urlpatterns", self.urlconf_module)
  File "/usr/local/lib/python3.5/dist-packages/django/utils/functional.py", line 33, in __get__
    res = instance.__dict__[self.name] = self.func(instance)
  File "/usr/local/lib/python3.5/dist-packages/django/core/urlresolvers.py", line 410, in urlconf_module
    return import_module(self.urlconf_name)
  File "/usr/lib/python3.5/importlib/__init__.py", line 126, in import_module
    return _bootstrap._gcd_import(name[level:], package, level)
  File "<frozen importlib._bootstrap>", line 986, in _gcd_import
  File "<frozen importlib._bootstrap>", line 969, in _find_and_load
  File "<frozen importlib._bootstrap>", line 958, in _find_and_load_unlocked
  File "<frozen importlib._bootstrap>", line 673, in _load_unlocked
  File "<frozen importlib._bootstrap_external>", line 665, in exec_module
  File "<frozen importlib._bootstrap>", line 222, in _call_with_frames_removed
  File "/opt/WebWord2Vec/Word2Vec/urls.py", line 23, in <module>
    url(r'^', include('WV.urls')),
  File "/usr/local/lib/python3.5/dist-packages/django/conf/urls/__init__.py", line 52, in include
    urlconf_module = import_module(urlconf_module)
  File "/usr/lib/python3.5/importlib/__init__.py", line 126, in import_module
    return _bootstrap._gcd_import(name[level:], package, level)
  File "<frozen importlib._bootstrap>", line 986, in _gcd_import
  File "<frozen importlib._bootstrap>", line 969, in _find_and_load
  File "<frozen importlib._bootstrap>", line 958, in _find_and_load_unlocked
  File "<frozen importlib._bootstrap>", line 673, in _load_unlocked
  File "<frozen importlib._bootstrap_external>", line 665, in exec_module
  File "<frozen importlib._bootstrap>", line 222, in _call_with_frames_removed
  File "/opt/WebWord2Vec/WV/urls.py", line 2, in <module>
    from WV import views
  File "/opt/WebWord2Vec/WV/views.py", line 59
    print(request.FILES['Data_xls'].id)
                                      ^
TabError: inconsistent use of tabs and spaces in indentation
Internal Server Error: /
Traceback (most recent call last):
  File "/usr/local/lib/python3.5/dist-packages/django/core/handlers/base.py", line 134, in get_response
    resolver_match = resolver.resolve(request.path_info)
  File "/usr/local/lib/python3.5/dist-packages/django/core/urlresolvers.py", line 374, in resolve
    for pattern in self.url_patterns:
  File "/usr/local/lib/python3.5/dist-packages/django/utils/functional.py", line 33, in __get__
    res = instance.__dict__[self.name] = self.func(instance)
  File "/usr/local/lib/python3.5/dist-packages/django/core/urlresolvers.py", line 417, in url_patterns
    patterns = getattr(self.urlconf_module, "urlpatterns", self.urlconf_module)
  File "/usr/local/lib/python3.5/dist-packages/django/utils/functional.py", line 33, in __get__
    res = instance.__dict__[self.name] = self.func(instance)
  File "/usr/local/lib/python3.5/dist-packages/django/core/urlresolvers.py", line 410, in urlconf_module
    return import_module(self.urlconf_name)
  File "/usr/lib/python3.5/importlib/__init__.py", line 126, in import_module
    return _bootstrap._gcd_import(name[level:], package, level)
  File "<frozen importlib._bootstrap>", line 986, in _gcd_import
  File "<frozen importlib._bootstrap>", line 969, in _find_and_load
  File "<frozen importlib._bootstrap>", line 958, in _find_and_load_unlocked
  File "<frozen importlib._bootstrap>", line 673, in _load_unlocked
  File "<frozen importlib._bootstrap_external>", line 665, in exec_module
  File "<frozen importlib._bootstrap>", line 222, in _call_with_frames_removed
  File "/opt/WebWord2Vec/Word2Vec/urls.py", line 23, in <module>
    url(r'^', include('WV.urls')),
  File "/usr/local/lib/python3.5/dist-packages/django/conf/urls/__init__.py", line 52, in include
    urlconf_module = import_module(urlconf_module)
  File "/usr/lib/python3.5/importlib/__init__.py", line 126, in import_module
    return _bootstrap._gcd_import(name[level:], package, level)
  File "<frozen importlib._bootstrap>", line 986, in _gcd_import
  File "<frozen importlib._bootstrap>", line 969, in _find_and_load
  File "<frozen importlib._bootstrap>", line 958, in _find_and_load_unlocked
  File "<frozen importlib._bootstrap>", line 673, in _load_unlocked
  File "<frozen importlib._bootstrap_external>", line 665, in exec_module
  File "<frozen importlib._bootstrap>", line 222, in _call_with_frames_removed
  File "/opt/WebWord2Vec/WV/urls.py", line 2, in <module>
    from WV import views
  File "/opt/WebWord2Vec/WV/views.py", line 53
    form_text.save()
                    ^
TabError: inconsistent use of tabs and spaces in indentation
Internal Server Error: /
Traceback (most recent call last):
  File "/usr/local/lib/python3.5/dist-packages/django/core/handlers/base.py", line 134, in get_response
    resolver_match = resolver.resolve(request.path_info)
  File "/usr/local/lib/python3.5/dist-packages/django/core/urlresolvers.py", line 374, in resolve
    for pattern in self.url_patterns:
  File "/usr/local/lib/python3.5/dist-packages/django/utils/functional.py", line 33, in __get__
    res = instance.__dict__[self.name] = self.func(instance)
  File "/usr/local/lib/python3.5/dist-packages/django/core/urlresolvers.py", line 417, in url_patterns
    patterns = getattr(self.urlconf_module, "urlpatterns", self.urlconf_module)
  File "/usr/local/lib/python3.5/dist-packages/django/utils/functional.py", line 33, in __get__
    res = instance.__dict__[self.name] = self.func(instance)
  File "/usr/local/lib/python3.5/dist-packages/django/core/urlresolvers.py", line 410, in urlconf_module
    return import_module(self.urlconf_name)
  File "/usr/lib/python3.5/importlib/__init__.py", line 126, in import_module
    return _bootstrap._gcd_import(name[level:], package, level)
  File "<frozen importlib._bootstrap>", line 986, in _gcd_import
  File "<frozen importlib._bootstrap>", line 969, in _find_and_load
  File "<frozen importlib._bootstrap>", line 958, in _find_and_load_unlocked
  File "<frozen importlib._bootstrap>", line 673, in _load_unlocked
  File "<frozen importlib._bootstrap_external>", line 665, in exec_module
  File "<frozen importlib._bootstrap>", line 222, in _call_with_frames_removed
  File "/opt/WebWord2Vec/Word2Vec/urls.py", line 23, in <module>
    url(r'^', include('WV.urls')),
  File "/usr/local/lib/python3.5/dist-packages/django/conf/urls/__init__.py", line 52, in include
    urlconf_module = import_module(urlconf_module)
  File "/usr/lib/python3.5/importlib/__init__.py", line 126, in import_module
    return _bootstrap._gcd_import(name[level:], package, level)
  File "<frozen importlib._bootstrap>", line 986, in _gcd_import
  File "<frozen importlib._bootstrap>", line 969, in _find_and_load
  File "<frozen importlib._bootstrap>", line 958, in _find_and_load_unlocked
  File "<frozen importlib._bootstrap>", line 673, in _load_unlocked
  File "<frozen importlib._bootstrap_external>", line 665, in exec_module
  File "<frozen importlib._bootstrap>", line 222, in _call_with_frames_removed
  File "/opt/WebWord2Vec/WV/urls.py", line 2, in <module>
    from WV import views
  File "/opt/WebWord2Vec/WV/views.py", line 53
    form_text.save()
                    ^
TabError: inconsistent use of tabs and spaces in indentation
Internal Server Error: /
Traceback (most recent call last):
  File "/usr/local/lib/python3.5/dist-packages/django/core/handlers/base.py", line 134, in get_response
    resolver_match = resolver.resolve(request.path_info)
  File "/usr/local/lib/python3.5/dist-packages/django/core/urlresolvers.py", line 374, in resolve
    for pattern in self.url_patterns:
  File "/usr/local/lib/python3.5/dist-packages/django/utils/functional.py", line 33, in __get__
    res = instance.__dict__[self.name] = self.func(instance)
  File "/usr/local/lib/python3.5/dist-packages/django/core/urlresolvers.py", line 417, in url_patterns
    patterns = getattr(self.urlconf_module, "urlpatterns", self.urlconf_module)
  File "/usr/local/lib/python3.5/dist-packages/django/utils/functional.py", line 33, in __get__
    res = instance.__dict__[self.name] = self.func(instance)
  File "/usr/local/lib/python3.5/dist-packages/django/core/urlresolvers.py", line 410, in urlconf_module
    return import_module(self.urlconf_name)
  File "/usr/lib/python3.5/importlib/__init__.py", line 126, in import_module
    return _bootstrap._gcd_import(name[level:], package, level)
  File "<frozen importlib._bootstrap>", line 986, in _gcd_import
  File "<frozen importlib._bootstrap>", line 969, in _find_and_load
  File "<frozen importlib._bootstrap>", line 958, in _find_and_load_unlocked
  File "<frozen importlib._bootstrap>", line 673, in _load_unlocked
  File "<frozen importlib._bootstrap_external>", line 665, in exec_module
  File "<frozen importlib._bootstrap>", line 222, in _call_with_frames_removed
  File "/opt/WebWord2Vec/Word2Vec/urls.py", line 23, in <module>
    url(r'^', include('WV.urls')),
  File "/usr/local/lib/python3.5/dist-packages/django/conf/urls/__init__.py", line 52, in include
    urlconf_module = import_module(urlconf_module)
  File "/usr/lib/python3.5/importlib/__init__.py", line 126, in import_module
    return _bootstrap._gcd_import(name[level:], package, level)
  File "<frozen importlib._bootstrap>", line 986, in _gcd_import
  File "<frozen importlib._bootstrap>", line 969, in _find_and_load
  File "<frozen importlib._bootstrap>", line 958, in _find_and_load_unlocked
  File "<frozen importlib._bootstrap>", line 673, in _load_unlocked
  File "<frozen importlib._bootstrap_external>", line 665, in exec_module
  File "<frozen importlib._bootstrap>", line 222, in _call_with_frames_removed
  File "/opt/WebWord2Vec/WV/urls.py", line 2, in <module>
    from WV import views
  File "/opt/WebWord2Vec/WV/views.py", line 53
    form_text.save()
                    ^
TabError: inconsistent use of tabs and spaces in indentation
Internal Server Error: /
Traceback (most recent call last):
  File "/usr/local/lib/python3.5/dist-packages/django/core/handlers/base.py", line 134, in get_response
    resolver_match = resolver.resolve(request.path_info)
  File "/usr/local/lib/python3.5/dist-packages/django/core/urlresolvers.py", line 374, in resolve
    for pattern in self.url_patterns:
  File "/usr/local/lib/python3.5/dist-packages/django/utils/functional.py", line 33, in __get__
    res = instance.__dict__[self.name] = self.func(instance)
  File "/usr/local/lib/python3.5/dist-packages/django/core/urlresolvers.py", line 417, in url_patterns
    patterns = getattr(self.urlconf_module, "urlpatterns", self.urlconf_module)
  File "/usr/local/lib/python3.5/dist-packages/django/utils/functional.py", line 33, in __get__
    res = instance.__dict__[self.name] = self.func(instance)
  File "/usr/local/lib/python3.5/dist-packages/django/core/urlresolvers.py", line 410, in urlconf_module
    return import_module(self.urlconf_name)
  File "/usr/lib/python3.5/importlib/__init__.py", line 126, in import_module
    return _bootstrap._gcd_import(name[level:], package, level)
  File "<frozen importlib._bootstrap>", line 986, in _gcd_import
  File "<frozen importlib._bootstrap>", line 969, in _find_and_load
  File "<frozen importlib._bootstrap>", line 958, in _find_and_load_unlocked
  File "<frozen importlib._bootstrap>", line 673, in _load_unlocked
  File "<frozen importlib._bootstrap_external>", line 665, in exec_module
  File "<frozen importlib._bootstrap>", line 222, in _call_with_frames_removed
  File "/opt/WebWord2Vec/Word2Vec/urls.py", line 23, in <module>
    url(r'^', include('WV.urls')),
  File "/usr/local/lib/python3.5/dist-packages/django/conf/urls/__init__.py", line 52, in include
    urlconf_module = import_module(urlconf_module)
  File "/usr/lib/python3.5/importlib/__init__.py", line 126, in import_module
    return _bootstrap._gcd_import(name[level:], package, level)
  File "<frozen importlib._bootstrap>", line 986, in _gcd_import
  File "<frozen importlib._bootstrap>", line 969, in _find_and_load
  File "<frozen importlib._bootstrap>", line 958, in _find_and_load_unlocked
  File "<frozen importlib._bootstrap>", line 673, in _load_unlocked
  File "<frozen importlib._bootstrap_external>", line 665, in exec_module
  File "<frozen importlib._bootstrap>", line 222, in _call_with_frames_removed
  File "/opt/WebWord2Vec/WV/urls.py", line 2, in <module>
    from WV import views
  File "/opt/WebWord2Vec/WV/views.py", line 53
    form_text.save()
                   ^
TabError: inconsistent use of tabs and spaces in indentation
Internal Server Error: /
Traceback (most recent call last):
  File "/usr/local/lib/python3.5/dist-packages/django/core/handlers/base.py", line 134, in get_response
    resolver_match = resolver.resolve(request.path_info)
  File "/usr/local/lib/python3.5/dist-packages/django/core/urlresolvers.py", line 374, in resolve
    for pattern in self.url_patterns:
  File "/usr/local/lib/python3.5/dist-packages/django/utils/functional.py", line 33, in __get__
    res = instance.__dict__[self.name] = self.func(instance)
  File "/usr/local/lib/python3.5/dist-packages/django/core/urlresolvers.py", line 417, in url_patterns
    patterns = getattr(self.urlconf_module, "urlpatterns", self.urlconf_module)
  File "/usr/local/lib/python3.5/dist-packages/django/utils/functional.py", line 33, in __get__
    res = instance.__dict__[self.name] = self.func(instance)
  File "/usr/local/lib/python3.5/dist-packages/django/core/urlresolvers.py", line 410, in urlconf_module
    return import_module(self.urlconf_name)
  File "/usr/lib/python3.5/importlib/__init__.py", line 126, in import_module
    return _bootstrap._gcd_import(name[level:], package, level)
  File "<frozen importlib._bootstrap>", line 986, in _gcd_import
  File "<frozen importlib._bootstrap>", line 969, in _find_and_load
  File "<frozen importlib._bootstrap>", line 958, in _find_and_load_unlocked
  File "<frozen importlib._bootstrap>", line 673, in _load_unlocked
  File "<frozen importlib._bootstrap_external>", line 665, in exec_module
  File "<frozen importlib._bootstrap>", line 222, in _call_with_frames_removed
  File "/opt/WebWord2Vec/Word2Vec/urls.py", line 23, in <module>
    url(r'^', include('WV.urls')),
  File "/usr/local/lib/python3.5/dist-packages/django/conf/urls/__init__.py", line 52, in include
    urlconf_module = import_module(urlconf_module)
  File "/usr/lib/python3.5/importlib/__init__.py", line 126, in import_module
    return _bootstrap._gcd_import(name[level:], package, level)
  File "<frozen importlib._bootstrap>", line 986, in _gcd_import
  File "<frozen importlib._bootstrap>", line 969, in _find_and_load
  File "<frozen importlib._bootstrap>", line 958, in _find_and_load_unlocked
  File "<frozen importlib._bootstrap>", line 673, in _load_unlocked
  File "<frozen importlib._bootstrap_external>", line 665, in exec_module
  File "<frozen importlib._bootstrap>", line 222, in _call_with_frames_removed
  File "/opt/WebWord2Vec/WV/urls.py", line 2, in <module>
    from WV import views
  File "/opt/WebWord2Vec/WV/views.py", line 53
    form_text.save()
                   ^
TabError: inconsistent use of tabs and spaces in indentation
Internal Server Error: /
Traceback (most recent call last):
  File "/usr/local/lib/python3.5/dist-packages/django/core/handlers/base.py", line 134, in get_response
    resolver_match = resolver.resolve(request.path_info)
  File "/usr/local/lib/python3.5/dist-packages/django/core/urlresolvers.py", line 374, in resolve
    for pattern in self.url_patterns:
  File "/usr/local/lib/python3.5/dist-packages/django/utils/functional.py", line 33, in __get__
    res = instance.__dict__[self.name] = self.func(instance)
  File "/usr/local/lib/python3.5/dist-packages/django/core/urlresolvers.py", line 417, in url_patterns
    patterns = getattr(self.urlconf_module, "urlpatterns", self.urlconf_module)
  File "/usr/local/lib/python3.5/dist-packages/django/utils/functional.py", line 33, in __get__
    res = instance.__dict__[self.name] = self.func(instance)
  File "/usr/local/lib/python3.5/dist-packages/django/core/urlresolvers.py", line 410, in urlconf_module
    return import_module(self.urlconf_name)
  File "/usr/lib/python3.5/importlib/__init__.py", line 126, in import_module
    return _bootstrap._gcd_import(name[level:], package, level)
  File "<frozen importlib._bootstrap>", line 986, in _gcd_import
  File "<frozen importlib._bootstrap>", line 969, in _find_and_load
  File "<frozen importlib._bootstrap>", line 958, in _find_and_load_unlocked
  File "<frozen importlib._bootstrap>", line 673, in _load_unlocked
  File "<frozen importlib._bootstrap_external>", line 665, in exec_module
  File "<frozen importlib._bootstrap>", line 222, in _call_with_frames_removed
  File "/opt/WebWord2Vec/Word2Vec/urls.py", line 23, in <module>
    url(r'^', include('WV.urls')),
  File "/usr/local/lib/python3.5/dist-packages/django/conf/urls/__init__.py", line 52, in include
    urlconf_module = import_module(urlconf_module)
  File "/usr/lib/python3.5/importlib/__init__.py", line 126, in import_module
    return _bootstrap._gcd_import(name[level:], package, level)
  File "<frozen importlib._bootstrap>", line 986, in _gcd_import
  File "<frozen importlib._bootstrap>", line 969, in _find_and_load
  File "<frozen importlib._bootstrap>", line 958, in _find_and_load_unlocked
  File "<frozen importlib._bootstrap>", line 673, in _load_unlocked
  File "<frozen importlib._bootstrap_external>", line 665, in exec_module
  File "<frozen importlib._bootstrap>", line 222, in _call_with_frames_removed
  File "/opt/WebWord2Vec/WV/urls.py", line 2, in <module>
    from WV import views
  File "/opt/WebWord2Vec/WV/views.py", line 53
    form_text.save()
                   ^
TabError: inconsistent use of tabs and spaces in indentation
Internal Server Error: /
Traceback (most recent call last):
  File "/usr/local/lib/python3.5/dist-packages/django/core/handlers/base.py", line 134, in get_response
    resolver_match = resolver.resolve(request.path_info)
  File "/usr/local/lib/python3.5/dist-packages/django/core/urlresolvers.py", line 374, in resolve
    for pattern in self.url_patterns:
  File "/usr/local/lib/python3.5/dist-packages/django/utils/functional.py", line 33, in __get__
    res = instance.__dict__[self.name] = self.func(instance)
  File "/usr/local/lib/python3.5/dist-packages/django/core/urlresolvers.py", line 417, in url_patterns
    patterns = getattr(self.urlconf_module, "urlpatterns", self.urlconf_module)
  File "/usr/local/lib/python3.5/dist-packages/django/utils/functional.py", line 33, in __get__
    res = instance.__dict__[self.name] = self.func(instance)
  File "/usr/local/lib/python3.5/dist-packages/django/core/urlresolvers.py", line 410, in urlconf_module
    return import_module(self.urlconf_name)
  File "/usr/lib/python3.5/importlib/__init__.py", line 126, in import_module
    return _bootstrap._gcd_import(name[level:], package, level)
  File "<frozen importlib._bootstrap>", line 986, in _gcd_import
  File "<frozen importlib._bootstrap>", line 969, in _find_and_load
  File "<frozen importlib._bootstrap>", line 958, in _find_and_load_unlocked
  File "<frozen importlib._bootstrap>", line 673, in _load_unlocked
  File "<frozen importlib._bootstrap_external>", line 665, in exec_module
  File "<frozen importlib._bootstrap>", line 222, in _call_with_frames_removed
  File "/opt/WebWord2Vec/Word2Vec/urls.py", line 23, in <module>
    url(r'^', include('WV.urls')),
  File "/usr/local/lib/python3.5/dist-packages/django/conf/urls/__init__.py", line 52, in include
    urlconf_module = import_module(urlconf_module)
  File "/usr/lib/python3.5/importlib/__init__.py", line 126, in import_module
    return _bootstrap._gcd_import(name[level:], package, level)
  File "<frozen importlib._bootstrap>", line 986, in _gcd_import
  File "<frozen importlib._bootstrap>", line 969, in _find_and_load
  File "<frozen importlib._bootstrap>", line 958, in _find_and_load_unlocked
  File "<frozen importlib._bootstrap>", line 673, in _load_unlocked
  File "<frozen importlib._bootstrap_external>", line 665, in exec_module
  File "<frozen importlib._bootstrap>", line 222, in _call_with_frames_removed
  File "/opt/WebWord2Vec/WV/urls.py", line 2, in <module>
    from WV import views
  File "/opt/WebWord2Vec/WV/views.py", line 53
    form_text.save()
                   ^
TabError: inconsistent use of tabs and spaces in indentation
Internal Server Error: /
Traceback (most recent call last):
  File "/usr/local/lib/python3.5/dist-packages/django/core/handlers/base.py", line 149, in get_response
    response = self.process_exception_by_middleware(e, request)
  File "/usr/local/lib/python3.5/dist-packages/django/core/handlers/base.py", line 147, in get_response
    response = wrapped_callback(request, *callback_args, **callback_kwargs)
  File "/opt/WebWord2Vec/WV/views.py", line 58, in MainPage
    tg=Tags(text_id=Data.objects.get(Data_xls=request.FILES['Data_xls']).id,tg=i)
  File "/usr/local/lib/python3.5/dist-packages/django/db/models/manager.py", line 122, in manager_method
    return getattr(self.get_queryset(), name)(*args, **kwargs)
  File "/usr/local/lib/python3.5/dist-packages/django/db/models/query.py", line 387, in get
    self.model._meta.object_name
WV.models.DoesNotExist: Data matching query does not exist.
Internal Server Error: /
Traceback (most recent call last):
  File "/usr/local/lib/python3.5/dist-packages/django/core/handlers/base.py", line 149, in get_response
    response = self.process_exception_by_middleware(e, request)
  File "/usr/local/lib/python3.5/dist-packages/django/core/handlers/base.py", line 147, in get_response
    response = wrapped_callback(request, *callback_args, **callback_kwargs)
  File "/opt/WebWord2Vec/WV/views.py", line 58, in MainPage
    tg=Tags(text_id=Data.objects.get(Data_xls=request.FILES['Data_xls']).id,tg=i)
  File "/usr/local/lib/python3.5/dist-packages/django/db/models/manager.py", line 122, in manager_method
    return getattr(self.get_queryset(), name)(*args, **kwargs)
  File "/usr/local/lib/python3.5/dist-packages/django/db/models/query.py", line 387, in get
    self.model._meta.object_name
WV.models.DoesNotExist: Data matching query does not exist.
Internal Server Error: /
Traceback (most recent call last):
  File "/usr/local/lib/python3.5/dist-packages/django/core/handlers/base.py", line 149, in get_response
    response = self.process_exception_by_middleware(e, request)
  File "/usr/local/lib/python3.5/dist-packages/django/core/handlers/base.py", line 147, in get_response
    response = wrapped_callback(request, *callback_args, **callback_kwargs)
  File "/opt/WebWord2Vec/WV/views.py", line 58, in MainPage
    tg=Tags(text_id=Data.objects.get(Data_xls=request.FILES['Data_xls']).id,tg=i)
  File "/usr/local/lib/python3.5/dist-packages/django/db/models/manager.py", line 122, in manager_method
    return getattr(self.get_queryset(), name)(*args, **kwargs)
  File "/usr/local/lib/python3.5/dist-packages/django/db/models/query.py", line 387, in get
    self.model._meta.object_name
WV.models.DoesNotExist: Data matching query does not exist.
Internal Server Error: /
Traceback (most recent call last):
  File "/usr/local/lib/python3.5/dist-packages/django/core/handlers/base.py", line 149, in get_response
    response = self.process_exception_by_middleware(e, request)
  File "/usr/local/lib/python3.5/dist-packages/django/core/handlers/base.py", line 147, in get_response
    response = wrapped_callback(request, *callback_args, **callback_kwargs)
  File "/opt/WebWord2Vec/WV/views.py", line 58, in MainPage
    tg=Tags(text_id=Data.objects.get(Data_xls=request.FILES['Data_xls']).id,tg=i)
  File "/usr/local/lib/python3.5/dist-packages/django/db/models/manager.py", line 122, in manager_method
    return getattr(self.get_queryset(), name)(*args, **kwargs)
  File "/usr/local/lib/python3.5/dist-packages/django/db/models/query.py", line 387, in get
    self.model._meta.object_name
WV.models.DoesNotExist: Data matching query does not exist.
Internal Server Error: /
Traceback (most recent call last):
  File "/usr/local/lib/python3.5/dist-packages/django/core/handlers/base.py", line 149, in get_response
    response = self.process_exception_by_middleware(e, request)
  File "/usr/local/lib/python3.5/dist-packages/django/core/handlers/base.py", line 147, in get_response
    response = wrapped_callback(request, *callback_args, **callback_kwargs)
  File "/opt/WebWord2Vec/WV/views.py", line 58, in MainPage
    tg=Tags(text_id=Data.objects.get(Data_xls=request.FILES['Data_xls']).id,tg=i)
  File "/usr/local/lib/python3.5/dist-packages/django/db/models/manager.py", line 122, in manager_method
    return getattr(self.get_queryset(), name)(*args, **kwargs)
  File "/usr/local/lib/python3.5/dist-packages/django/db/models/query.py", line 387, in get
    self.model._meta.object_name
WV.models.DoesNotExist: Data matching query does not exist.
Internal Server Error: /
Traceback (most recent call last):
  File "/usr/local/lib/python3.5/dist-packages/django/core/handlers/base.py", line 149, in get_response
    response = self.process_exception_by_middleware(e, request)
  File "/usr/local/lib/python3.5/dist-packages/django/core/handlers/base.py", line 147, in get_response
    response = wrapped_callback(request, *callback_args, **callback_kwargs)
  File "/opt/WebWord2Vec/WV/views.py", line 58, in MainPage
    tg=Tags(text_id=Data.objects.get(Data_xls=request.FILES['Data_xls']).id,tg=i)
  File "/usr/local/lib/python3.5/dist-packages/django/db/models/manager.py", line 122, in manager_method
    return getattr(self.get_queryset(), name)(*args, **kwargs)
  File "/usr/local/lib/python3.5/dist-packages/django/db/models/query.py", line 387, in get
    self.model._meta.object_name
WV.models.DoesNotExist: Data matching query does not exist.
Internal Server Error: /
Traceback (most recent call last):
  File "/usr/local/lib/python3.5/dist-packages/django/core/handlers/base.py", line 149, in get_response
    response = self.process_exception_by_middleware(e, request)
  File "/usr/local/lib/python3.5/dist-packages/django/core/handlers/base.py", line 147, in get_response
    response = wrapped_callback(request, *callback_args, **callback_kwargs)
  File "/opt/WebWord2Vec/WV/views.py", line 58, in MainPage
    tg=Tags(text_id=Data.objects.get(Data_xls=request.FILES['Data_xls']).id,tg=i)
  File "/usr/local/lib/python3.5/dist-packages/django/db/models/manager.py", line 122, in manager_method
    return getattr(self.get_queryset(), name)(*args, **kwargs)
  File "/usr/local/lib/python3.5/dist-packages/django/db/models/query.py", line 387, in get
    self.model._meta.object_name
WV.models.DoesNotExist: Data matching query does not exist.
Internal Server Error: /
Traceback (most recent call last):
  File "/usr/local/lib/python3.5/dist-packages/django/core/handlers/base.py", line 149, in get_response
    response = self.process_exception_by_middleware(e, request)
  File "/usr/local/lib/python3.5/dist-packages/django/core/handlers/base.py", line 147, in get_response
    response = wrapped_callback(request, *callback_args, **callback_kwargs)
  File "/opt/WebWord2Vec/WV/views.py", line 58, in MainPage
    tg=Tags(text_id=Data.objects.get(Data_xls=request.FILES['Data_xls']).id,tg=i)
  File "/usr/local/lib/python3.5/dist-packages/django/db/models/manager.py", line 122, in manager_method
    return getattr(self.get_queryset(), name)(*args, **kwargs)
  File "/usr/local/lib/python3.5/dist-packages/django/db/models/query.py", line 387, in get
    self.model._meta.object_name
WV.models.DoesNotExist: Data matching query does not exist.
Internal Server Error: /options/269/
Traceback (most recent call last):
  File "/usr/local/lib/python3.5/dist-packages/django/core/handlers/base.py", line 149, in get_response
    response = self.process_exception_by_middleware(e, request)
  File "/usr/local/lib/python3.5/dist-packages/django/core/handlers/base.py", line 147, in get_response
    response = wrapped_callback(request, *callback_args, **callback_kwargs)
  File "/opt/WebWord2Vec/WV/views.py", line 247, in Enteroptions
    int(request.POST['minc'])))
  File "/opt/WebWord2Vec/WV/views.py", line 242, in Map
    BuildHtmlMap()
  File "/opt/WebWord2Vec/WV/views.py", line 213, in BuildHtmlMap
    export_png(p1,os.path.join(STATICFILES_DIRS,picture_name))
  File "/usr/lib/python3.5/posixpath.py", line 89, in join
    genericpath._check_arg_types('join', a, *p)
  File "/usr/lib/python3.5/genericpath.py", line 143, in _check_arg_types
    (funcname, s.__class__.__name__)) from None
TypeError: join() argument must be str or bytes, not 'list'
Internal Server Error: /maps/270/1/
Traceback (most recent call last):
  File "/usr/local/lib/python3.5/dist-packages/django/template/base.py", line 506, in parse
    compile_func = self.tags[command]
KeyError: 'opt.img'

During handling of the above exception, another exception occurred:

Traceback (most recent call last):
  File "/usr/local/lib/python3.5/dist-packages/django/core/handlers/base.py", line 149, in get_response
    response = self.process_exception_by_middleware(e, request)
  File "/usr/local/lib/python3.5/dist-packages/django/core/handlers/base.py", line 147, in get_response
    response = wrapped_callback(request, *callback_args, **callback_kwargs)
  File "/opt/WebWord2Vec/WV/views.py", line 336, in Maps
    return render_to_response('maps.html',args)
  File "/usr/local/lib/python3.5/dist-packages/django/shortcuts.py", line 39, in render_to_response
    content = loader.render_to_string(template_name, context, using=using)
  File "/usr/local/lib/python3.5/dist-packages/django/template/loader.py", line 96, in render_to_string
    template = get_template(template_name, using=using)
  File "/usr/local/lib/python3.5/dist-packages/django/template/loader.py", line 32, in get_template
    return engine.get_template(template_name, dirs)
  File "/usr/local/lib/python3.5/dist-packages/django/template/backends/django.py", line 40, in get_template
    return Template(self.engine.get_template(template_name, dirs), self)
  File "/usr/local/lib/python3.5/dist-packages/django/template/engine.py", line 190, in get_template
    template, origin = self.find_template(template_name, dirs)
  File "/usr/local/lib/python3.5/dist-packages/django/template/engine.py", line 157, in find_template
    name, template_dirs=dirs, skip=skip,
  File "/usr/local/lib/python3.5/dist-packages/django/template/loaders/base.py", line 46, in get_template
    contents, origin, origin.template_name, self.engine,
  File "/usr/local/lib/python3.5/dist-packages/django/template/base.py", line 189, in __init__
    self.nodelist = self.compile_nodelist()
  File "/usr/local/lib/python3.5/dist-packages/django/template/base.py", line 230, in compile_nodelist
    return parser.parse()
  File "/usr/local/lib/python3.5/dist-packages/django/template/base.py", line 514, in parse
    raise self.error(token, e)
  File "/usr/local/lib/python3.5/dist-packages/django/template/base.py", line 512, in parse
    compiled_result = compile_func(self, token)
  File "/usr/local/lib/python3.5/dist-packages/django/template/loader_tags.py", line 267, in do_extends
    nodelist = parser.parse()
  File "/usr/local/lib/python3.5/dist-packages/django/template/base.py", line 514, in parse
    raise self.error(token, e)
  File "/usr/local/lib/python3.5/dist-packages/django/template/base.py", line 512, in parse
    compiled_result = compile_func(self, token)
  File "/usr/local/lib/python3.5/dist-packages/django/template/loader_tags.py", line 241, in do_block
    nodelist = parser.parse(('endblock',))
  File "/usr/local/lib/python3.5/dist-packages/django/template/base.py", line 514, in parse
    raise self.error(token, e)
  File "/usr/local/lib/python3.5/dist-packages/django/template/base.py", line 512, in parse
    compiled_result = compile_func(self, token)
  File "/usr/local/lib/python3.5/dist-packages/django/template/defaulttags.py", line 1028, in do_if
    nodelist = parser.parse(('elif', 'else', 'endif'))
  File "/usr/local/lib/python3.5/dist-packages/django/template/base.py", line 514, in parse
    raise self.error(token, e)
  File "/usr/local/lib/python3.5/dist-packages/django/template/base.py", line 512, in parse
    compiled_result = compile_func(self, token)
  File "/usr/local/lib/python3.5/dist-packages/django/template/defaulttags.py", line 886, in do_for
    nodelist_loop = parser.parse(('empty', 'endfor',))
  File "/usr/local/lib/python3.5/dist-packages/django/template/base.py", line 514, in parse
    raise self.error(token, e)
  File "/usr/local/lib/python3.5/dist-packages/django/template/base.py", line 512, in parse
    compiled_result = compile_func(self, token)
  File "/usr/local/lib/python3.5/dist-packages/django/template/defaulttags.py", line 1028, in do_if
    nodelist = parser.parse(('elif', 'else', 'endif'))
  File "/usr/local/lib/python3.5/dist-packages/django/template/base.py", line 508, in parse
    self.invalid_block_tag(token, command, parse_until)
  File "/usr/local/lib/python3.5/dist-packages/django/template/base.py", line 562, in invalid_block_tag
    get_text_list(["'%s'" % p for p in parse_until]),
django.template.exceptions.TemplateSyntaxError: Invalid block tag on line 21: 'opt.img', expected 'elif', 'else' or 'endif'. Did you forget to register or load this tag?
Internal Server Error: /
Traceback (most recent call last):
  File "/usr/local/lib/python3.5/dist-packages/django/core/handlers/base.py", line 149, in get_response
    response = self.process_exception_by_middleware(e, request)
  File "/usr/local/lib/python3.5/dist-packages/django/core/handlers/base.py", line 147, in get_response
    response = wrapped_callback(request, *callback_args, **callback_kwargs)
  File "/opt/WebWord2Vec/WV/views.py", line 58, in MainPage
    tg=Tags(text_id=Data.objects.get(Data_xls=request.FILES['Data_xls']).id,tg=i)
  File "/usr/local/lib/python3.5/dist-packages/django/db/models/manager.py", line 122, in manager_method
    return getattr(self.get_queryset(), name)(*args, **kwargs)
  File "/usr/local/lib/python3.5/dist-packages/django/db/models/query.py", line 387, in get
    self.model._meta.object_name
WV.models.DoesNotExist: Data matching query does not exist.
Internal Server Error: /maps/270/1/
Traceback (most recent call last):
  File "/usr/local/lib/python3.5/dist-packages/django/template/base.py", line 506, in parse
    compile_func = self.tags[command]
KeyError: 'opt.img'

During handling of the above exception, another exception occurred:

Traceback (most recent call last):
  File "/usr/local/lib/python3.5/dist-packages/django/core/handlers/base.py", line 149, in get_response
    response = self.process_exception_by_middleware(e, request)
  File "/usr/local/lib/python3.5/dist-packages/django/core/handlers/base.py", line 147, in get_response
    response = wrapped_callback(request, *callback_args, **callback_kwargs)
  File "/opt/WebWord2Vec/WV/views.py", line 336, in Maps
    return render_to_response('maps.html',args)
  File "/usr/local/lib/python3.5/dist-packages/django/shortcuts.py", line 39, in render_to_response
    content = loader.render_to_string(template_name, context, using=using)
  File "/usr/local/lib/python3.5/dist-packages/django/template/loader.py", line 96, in render_to_string
    template = get_template(template_name, using=using)
  File "/usr/local/lib/python3.5/dist-packages/django/template/loader.py", line 32, in get_template
    return engine.get_template(template_name, dirs)
  File "/usr/local/lib/python3.5/dist-packages/django/template/backends/django.py", line 40, in get_template
    return Template(self.engine.get_template(template_name, dirs), self)
  File "/usr/local/lib/python3.5/dist-packages/django/template/engine.py", line 190, in get_template
    template, origin = self.find_template(template_name, dirs)
  File "/usr/local/lib/python3.5/dist-packages/django/template/engine.py", line 157, in find_template
    name, template_dirs=dirs, skip=skip,
  File "/usr/local/lib/python3.5/dist-packages/django/template/loaders/base.py", line 46, in get_template
    contents, origin, origin.template_name, self.engine,
  File "/usr/local/lib/python3.5/dist-packages/django/template/base.py", line 189, in __init__
    self.nodelist = self.compile_nodelist()
  File "/usr/local/lib/python3.5/dist-packages/django/template/base.py", line 230, in compile_nodelist
    return parser.parse()
  File "/usr/local/lib/python3.5/dist-packages/django/template/base.py", line 514, in parse
    raise self.error(token, e)
  File "/usr/local/lib/python3.5/dist-packages/django/template/base.py", line 512, in parse
    compiled_result = compile_func(self, token)
  File "/usr/local/lib/python3.5/dist-packages/django/template/loader_tags.py", line 267, in do_extends
    nodelist = parser.parse()
  File "/usr/local/lib/python3.5/dist-packages/django/template/base.py", line 514, in parse
    raise self.error(token, e)
  File "/usr/local/lib/python3.5/dist-packages/django/template/base.py", line 512, in parse
    compiled_result = compile_func(self, token)
  File "/usr/local/lib/python3.5/dist-packages/django/template/loader_tags.py", line 241, in do_block
    nodelist = parser.parse(('endblock',))
  File "/usr/local/lib/python3.5/dist-packages/django/template/base.py", line 514, in parse
    raise self.error(token, e)
  File "/usr/local/lib/python3.5/dist-packages/django/template/base.py", line 512, in parse
    compiled_result = compile_func(self, token)
  File "/usr/local/lib/python3.5/dist-packages/django/template/defaulttags.py", line 1028, in do_if
    nodelist = parser.parse(('elif', 'else', 'endif'))
  File "/usr/local/lib/python3.5/dist-packages/django/template/base.py", line 514, in parse
    raise self.error(token, e)
  File "/usr/local/lib/python3.5/dist-packages/django/template/base.py", line 512, in parse
    compiled_result = compile_func(self, token)
  File "/usr/local/lib/python3.5/dist-packages/django/template/defaulttags.py", line 886, in do_for
    nodelist_loop = parser.parse(('empty', 'endfor',))
  File "/usr/local/lib/python3.5/dist-packages/django/template/base.py", line 514, in parse
    raise self.error(token, e)
  File "/usr/local/lib/python3.5/dist-packages/django/template/base.py", line 512, in parse
    compiled_result = compile_func(self, token)
  File "/usr/local/lib/python3.5/dist-packages/django/template/defaulttags.py", line 1028, in do_if
    nodelist = parser.parse(('elif', 'else', 'endif'))
  File "/usr/local/lib/python3.5/dist-packages/django/template/base.py", line 508, in parse
    self.invalid_block_tag(token, command, parse_until)
  File "/usr/local/lib/python3.5/dist-packages/django/template/base.py", line 562, in invalid_block_tag
    get_text_list(["'%s'" % p for p in parse_until]),
django.template.exceptions.TemplateSyntaxError: Invalid block tag on line 21: 'opt.img', expected 'elif', 'else' or 'endif'. Did you forget to register or load this tag?
Forbidden (CSRF token missing or incorrect.): /
Internal Server Error: /options/270/
Traceback (most recent call last):
  File "/usr/local/lib/python3.5/dist-packages/django/core/handlers/base.py", line 149, in get_response
    response = self.process_exception_by_middleware(e, request)
  File "/usr/local/lib/python3.5/dist-packages/django/core/handlers/base.py", line 147, in get_response
    response = wrapped_callback(request, *callback_args, **callback_kwargs)
  File "/opt/WebWord2Vec/WV/views.py", line 247, in Enteroptions
    int(request.POST['minc'])))
  File "/opt/WebWord2Vec/WV/views.py", line 235, in Map
    model = Word2Vec(Words, size=size, window=win, min_count=minc)
  File "/usr/local/lib/python3.5/dist-packages/gensim/models/word2vec.py", line 505, in __init__
    start_alpha=self.alpha, end_alpha=self.min_alpha)
  File "/usr/local/lib/python3.5/dist-packages/gensim/models/word2vec.py", line 832, in train
    raise RuntimeError("you must first build vocabulary before training the model")
RuntimeError: you must first build vocabulary before training the model
Internal Server Error: /options/270/
Traceback (most recent call last):
  File "/usr/local/lib/python3.5/dist-packages/django/core/handlers/base.py", line 149, in get_response
    response = self.process_exception_by_middleware(e, request)
  File "/usr/local/lib/python3.5/dist-packages/django/core/handlers/base.py", line 147, in get_response
    response = wrapped_callback(request, *callback_args, **callback_kwargs)
  File "/opt/WebWord2Vec/WV/views.py", line 247, in Enteroptions
    int(request.POST['minc'])))
  File "/opt/WebWord2Vec/WV/views.py", line 235, in Map
    model = Word2Vec(Words, size=size, window=win, min_count=minc)
  File "/usr/local/lib/python3.5/dist-packages/gensim/models/word2vec.py", line 505, in __init__
    start_alpha=self.alpha, end_alpha=self.min_alpha)
  File "/usr/local/lib/python3.5/dist-packages/gensim/models/word2vec.py", line 832, in train
    raise RuntimeError("you must first build vocabulary before training the model")
RuntimeError: you must first build vocabulary before training the model
Internal Server Error: /options/270/
Traceback (most recent call last):
  File "/usr/local/lib/python3.5/dist-packages/django/core/handlers/base.py", line 149, in get_response
    response = self.process_exception_by_middleware(e, request)
  File "/usr/local/lib/python3.5/dist-packages/django/core/handlers/base.py", line 147, in get_response
    response = wrapped_callback(request, *callback_args, **callback_kwargs)
  File "/opt/WebWord2Vec/WV/views.py", line 247, in Enteroptions
    int(request.POST['minc'])))
  File "/opt/WebWord2Vec/WV/views.py", line 235, in Map
    model = Word2Vec(Words, size=size, window=win, min_count=minc)
  File "/usr/local/lib/python3.5/dist-packages/gensim/models/word2vec.py", line 505, in __init__
    start_alpha=self.alpha, end_alpha=self.min_alpha)
  File "/usr/local/lib/python3.5/dist-packages/gensim/models/word2vec.py", line 832, in train
    raise RuntimeError("you must first build vocabulary before training the model")
RuntimeError: you must first build vocabulary before training the model
Internal Server Error: /options/270/
Traceback (most recent call last):
  File "/usr/local/lib/python3.5/dist-packages/django/core/handlers/base.py", line 149, in get_response
    response = self.process_exception_by_middleware(e, request)
  File "/usr/local/lib/python3.5/dist-packages/django/core/handlers/base.py", line 147, in get_response
    response = wrapped_callback(request, *callback_args, **callback_kwargs)
  File "/opt/WebWord2Vec/WV/views.py", line 247, in Enteroptions
    int(request.POST['minc'])))
  File "/opt/WebWord2Vec/WV/views.py", line 235, in Map
    model = Word2Vec(Words, size=size, window=win, min_count=minc)
  File "/usr/local/lib/python3.5/dist-packages/gensim/models/word2vec.py", line 505, in __init__
    start_alpha=self.alpha, end_alpha=self.min_alpha)
  File "/usr/local/lib/python3.5/dist-packages/gensim/models/word2vec.py", line 832, in train
    raise RuntimeError("you must first build vocabulary before training the model")
RuntimeError: you must first build vocabulary before training the model
Internal Server Error: /
Traceback (most recent call last):
  File "/usr/local/lib/python3.5/dist-packages/django/core/handlers/base.py", line 149, in get_response
    response = self.process_exception_by_middleware(e, request)
  File "/usr/local/lib/python3.5/dist-packages/django/core/handlers/base.py", line 147, in get_response
    response = wrapped_callback(request, *callback_args, **callback_kwargs)
  File "/opt/WebWord2Vec/WV/views.py", line 58, in MainPage
    tg=Tags(text_id=Data.objects.get(Data_xls=request.FILES['Data_xls']).id,tg=i)
  File "/usr/local/lib/python3.5/dist-packages/django/db/models/manager.py", line 122, in manager_method
    return getattr(self.get_queryset(), name)(*args, **kwargs)
  File "/usr/local/lib/python3.5/dist-packages/django/db/models/query.py", line 387, in get
    self.model._meta.object_name
WV.models.DoesNotExist: Data matching query does not exist.
Internal Server Error: /
Traceback (most recent call last):
  File "/usr/local/lib/python3.5/dist-packages/django/core/handlers/base.py", line 149, in get_response
    response = self.process_exception_by_middleware(e, request)
  File "/usr/local/lib/python3.5/dist-packages/django/core/handlers/base.py", line 147, in get_response
    response = wrapped_callback(request, *callback_args, **callback_kwargs)
  File "/opt/WebWord2Vec/WV/views.py", line 58, in MainPage
    tg=Tags(text_id=Data.objects.get(Data_xls=request.FILES['Data_xls']).id,tg=i)
  File "/usr/local/lib/python3.5/dist-packages/django/db/models/manager.py", line 122, in manager_method
    return getattr(self.get_queryset(), name)(*args, **kwargs)
  File "/usr/local/lib/python3.5/dist-packages/django/db/models/query.py", line 387, in get
    self.model._meta.object_name
WV.models.DoesNotExist: Data matching query does not exist.
Internal Server Error: /
Traceback (most recent call last):
  File "/usr/local/lib/python3.5/dist-packages/django/core/handlers/base.py", line 149, in get_response
    response = self.process_exception_by_middleware(e, request)
  File "/usr/local/lib/python3.5/dist-packages/django/core/handlers/base.py", line 147, in get_response
    response = wrapped_callback(request, *callback_args, **callback_kwargs)
  File "/opt/WebWord2Vec/WV/views.py", line 58, in MainPage
    tg=Tags(text_id=Data.objects.get(Data_xls=request.FILES['Data_xls']).id,tg=i)
  File "/usr/local/lib/python3.5/dist-packages/django/db/models/manager.py", line 122, in manager_method
    return getattr(self.get_queryset(), name)(*args, **kwargs)
  File "/usr/local/lib/python3.5/dist-packages/django/db/models/query.py", line 387, in get
    self.model._meta.object_name
WV.models.DoesNotExist: Data matching query does not exist.
Internal Server Error: /
Traceback (most recent call last):
  File "/usr/local/lib/python3.5/dist-packages/django/core/handlers/base.py", line 149, in get_response
    response = self.process_exception_by_middleware(e, request)
  File "/usr/local/lib/python3.5/dist-packages/django/core/handlers/base.py", line 147, in get_response
    response = wrapped_callback(request, *callback_args, **callback_kwargs)
  File "/opt/WebWord2Vec/WV/views.py", line 58, in MainPage
    tg=Tags(text_id=Data.objects.get(Data_xls=request.FILES['Data_xls']).id,tg=i)
  File "/usr/local/lib/python3.5/dist-packages/django/db/models/manager.py", line 122, in manager_method
    return getattr(self.get_queryset(), name)(*args, **kwargs)
  File "/usr/local/lib/python3.5/dist-packages/django/db/models/query.py", line 387, in get
    self.model._meta.object_name
WV.models.DoesNotExist: Data matching query does not exist.
Internal Server Error: /
Traceback (most recent call last):
  File "/usr/local/lib/python3.5/dist-packages/django/core/handlers/base.py", line 149, in get_response
    response = self.process_exception_by_middleware(e, request)
  File "/usr/local/lib/python3.5/dist-packages/django/core/handlers/base.py", line 147, in get_response
    response = wrapped_callback(request, *callback_args, **callback_kwargs)
  File "/opt/WebWord2Vec/WV/views.py", line 58, in MainPage
    tg=Tags(text_id=Data.objects.get(Data_xls=request.FILES['Data_xls']).id,tg=i)
  File "/usr/local/lib/python3.5/dist-packages/django/db/models/manager.py", line 122, in manager_method
    return getattr(self.get_queryset(), name)(*args, **kwargs)
  File "/usr/local/lib/python3.5/dist-packages/django/db/models/query.py", line 387, in get
    self.model._meta.object_name
WV.models.DoesNotExist: Data matching query does not exist.
Internal Server Error: /
Traceback (most recent call last):
  File "/usr/local/lib/python3.5/dist-packages/django/core/handlers/base.py", line 149, in get_response
    response = self.process_exception_by_middleware(e, request)
  File "/usr/local/lib/python3.5/dist-packages/django/core/handlers/base.py", line 147, in get_response
    response = wrapped_callback(request, *callback_args, **callback_kwargs)
  File "/opt/WebWord2Vec/WV/views.py", line 58, in MainPage
    tg=Tags(text_id=Data.objects.get(Data_xls=request.FILES['Data_xls']).id,tg=i)
  File "/usr/local/lib/python3.5/dist-packages/django/db/models/manager.py", line 122, in manager_method
    return getattr(self.get_queryset(), name)(*args, **kwargs)
  File "/usr/local/lib/python3.5/dist-packages/django/db/models/query.py", line 387, in get
    self.model._meta.object_name
WV.models.DoesNotExist: Data matching query does not exist.
Internal Server Error: /
Traceback (most recent call last):
  File "/usr/local/lib/python3.5/dist-packages/django/core/handlers/base.py", line 149, in get_response
    response = self.process_exception_by_middleware(e, request)
  File "/usr/local/lib/python3.5/dist-packages/django/core/handlers/base.py", line 147, in get_response
    response = wrapped_callback(request, *callback_args, **callback_kwargs)
  File "/opt/WebWord2Vec/WV/views.py", line 58, in MainPage
    tg=Tags(text_id=Data.objects.get(Data_xls=request.FILES['Data_xls']).id,tg=i)
  File "/usr/local/lib/python3.5/dist-packages/django/db/models/manager.py", line 122, in manager_method
    return getattr(self.get_queryset(), name)(*args, **kwargs)
  File "/usr/local/lib/python3.5/dist-packages/django/db/models/query.py", line 387, in get
    self.model._meta.object_name
WV.models.DoesNotExist: Data matching query does not exist.
Internal Server Error: /
Traceback (most recent call last):
  File "/usr/local/lib/python3.5/dist-packages/django/core/handlers/base.py", line 149, in get_response
    response = self.process_exception_by_middleware(e, request)
  File "/usr/local/lib/python3.5/dist-packages/django/core/handlers/base.py", line 147, in get_response
    response = wrapped_callback(request, *callback_args, **callback_kwargs)
  File "/opt/WebWord2Vec/WV/views.py", line 58, in MainPage
    tg=Tags(text_id=Data.objects.get(Data_xls=request.FILES['Data_xls']).id,tg=i)
  File "/usr/local/lib/python3.5/dist-packages/django/db/models/manager.py", line 122, in manager_method
    return getattr(self.get_queryset(), name)(*args, **kwargs)
  File "/usr/local/lib/python3.5/dist-packages/django/db/models/query.py", line 387, in get
    self.model._meta.object_name
WV.models.DoesNotExist: Data matching query does not exist.
Internal Server Error: /
Traceback (most recent call last):
  File "/usr/local/lib/python3.5/dist-packages/django/core/handlers/base.py", line 149, in get_response
    response = self.process_exception_by_middleware(e, request)
  File "/usr/local/lib/python3.5/dist-packages/django/core/handlers/base.py", line 147, in get_response
    response = wrapped_callback(request, *callback_args, **callback_kwargs)
  File "/opt/WebWord2Vec/WV/views.py", line 58, in MainPage
    tg=Tags(text_id=Data.objects.get(Data_xls=request.FILES['Data_xls']).id,tg=i)
  File "/usr/local/lib/python3.5/dist-packages/django/db/models/manager.py", line 122, in manager_method
    return getattr(self.get_queryset(), name)(*args, **kwargs)
  File "/usr/local/lib/python3.5/dist-packages/django/db/models/query.py", line 387, in get
    self.model._meta.object_name
WV.models.DoesNotExist: Data matching query does not exist.
Internal Server Error: /
Traceback (most recent call last):
  File "/usr/local/lib/python3.5/dist-packages/django/core/handlers/base.py", line 149, in get_response
    response = self.process_exception_by_middleware(e, request)
  File "/usr/local/lib/python3.5/dist-packages/django/core/handlers/base.py", line 147, in get_response
    response = wrapped_callback(request, *callback_args, **callback_kwargs)
  File "/opt/WebWord2Vec/WV/views.py", line 58, in MainPage
    tg=Tags(text_id=Data.objects.get(Data_xls=request.FILES['Data_xls']).id,tg=i)
  File "/usr/local/lib/python3.5/dist-packages/django/db/models/manager.py", line 122, in manager_method
    return getattr(self.get_queryset(), name)(*args, **kwargs)
  File "/usr/local/lib/python3.5/dist-packages/django/db/models/query.py", line 387, in get
    self.model._meta.object_name
WV.models.DoesNotExist: Data matching query does not exist.
Internal Server Error: /
Traceback (most recent call last):
  File "/usr/local/lib/python3.5/dist-packages/django/core/handlers/base.py", line 149, in get_response
    response = self.process_exception_by_middleware(e, request)
  File "/usr/local/lib/python3.5/dist-packages/django/core/handlers/base.py", line 147, in get_response
    response = wrapped_callback(request, *callback_args, **callback_kwargs)
  File "/opt/WebWord2Vec/WV/views.py", line 58, in MainPage
    tg=Tags(text_id=Data.objects.get(Data_xls=request.FILES['Data_xls']).id,tg=i)
  File "/usr/local/lib/python3.5/dist-packages/django/db/models/manager.py", line 122, in manager_method
    return getattr(self.get_queryset(), name)(*args, **kwargs)
  File "/usr/local/lib/python3.5/dist-packages/django/db/models/query.py", line 387, in get
    self.model._meta.object_name
WV.models.DoesNotExist: Data matching query does not exist.
Internal Server Error: /
Traceback (most recent call last):
  File "/usr/local/lib/python3.5/dist-packages/django/core/handlers/base.py", line 149, in get_response
    response = self.process_exception_by_middleware(e, request)
  File "/usr/local/lib/python3.5/dist-packages/django/core/handlers/base.py", line 147, in get_response
    response = wrapped_callback(request, *callback_args, **callback_kwargs)
  File "/opt/WebWord2Vec/WV/views.py", line 58, in MainPage
    tg=Tags(text_id=Data.objects.get(Data_xls=request.FILES['Data_xls']).id,tg=i)
  File "/usr/local/lib/python3.5/dist-packages/django/db/models/manager.py", line 122, in manager_method
    return getattr(self.get_queryset(), name)(*args, **kwargs)
  File "/usr/local/lib/python3.5/dist-packages/django/db/models/query.py", line 387, in get
    self.model._meta.object_name
WV.models.DoesNotExist: Data matching query does not exist.
Internal Server Error: /
Traceback (most recent call last):
  File "/usr/local/lib/python3.5/dist-packages/django/core/handlers/base.py", line 149, in get_response
    response = self.process_exception_by_middleware(e, request)
  File "/usr/local/lib/python3.5/dist-packages/django/core/handlers/base.py", line 147, in get_response
    response = wrapped_callback(request, *callback_args, **callback_kwargs)
  File "/opt/WebWord2Vec/WV/views.py", line 58, in MainPage
    tg=Tags(text_id=Data.objects.get(Data_xls=request.FILES['Data_xls']).id,tg=i)
  File "/usr/local/lib/python3.5/dist-packages/django/db/models/manager.py", line 122, in manager_method
    return getattr(self.get_queryset(), name)(*args, **kwargs)
  File "/usr/local/lib/python3.5/dist-packages/django/db/models/query.py", line 387, in get
    self.model._meta.object_name
WV.models.DoesNotExist: Data matching query does not exist.
Internal Server Error: /
Traceback (most recent call last):
  File "/usr/local/lib/python3.5/dist-packages/django/core/handlers/base.py", line 149, in get_response
    response = self.process_exception_by_middleware(e, request)
  File "/usr/local/lib/python3.5/dist-packages/django/core/handlers/base.py", line 147, in get_response
    response = wrapped_callback(request, *callback_args, **callback_kwargs)
  File "/opt/WebWord2Vec/WV/views.py", line 58, in MainPage
    tg=Tags(text_id=Data.objects.get(Data_xls=request.FILES['Data_xls']).id,tg=i)
  File "/usr/local/lib/python3.5/dist-packages/django/db/models/manager.py", line 122, in manager_method
    return getattr(self.get_queryset(), name)(*args, **kwargs)
  File "/usr/local/lib/python3.5/dist-packages/django/db/models/query.py", line 387, in get
    self.model._meta.object_name
WV.models.DoesNotExist: Data matching query does not exist.
Internal Server Error: /
Traceback (most recent call last):
  File "/usr/local/lib/python3.5/dist-packages/django/core/handlers/base.py", line 149, in get_response
    response = self.process_exception_by_middleware(e, request)
  File "/usr/local/lib/python3.5/dist-packages/django/core/handlers/base.py", line 147, in get_response
    response = wrapped_callback(request, *callback_args, **callback_kwargs)
  File "/opt/WebWord2Vec/WV/views.py", line 58, in MainPage
    tg=Tags(text_id=Data.objects.get(Data_xls=request.FILES['Data_xls']).id,tg=i)
  File "/usr/local/lib/python3.5/dist-packages/django/db/models/manager.py", line 122, in manager_method
    return getattr(self.get_queryset(), name)(*args, **kwargs)
  File "/usr/local/lib/python3.5/dist-packages/django/db/models/query.py", line 387, in get
    self.model._meta.object_name
WV.models.DoesNotExist: Data matching query does not exist.
Internal Server Error: /
Traceback (most recent call last):
  File "/usr/local/lib/python3.5/dist-packages/django/core/handlers/base.py", line 149, in get_response
    response = self.process_exception_by_middleware(e, request)
  File "/usr/local/lib/python3.5/dist-packages/django/core/handlers/base.py", line 147, in get_response
    response = wrapped_callback(request, *callback_args, **callback_kwargs)
  File "/opt/WebWord2Vec/WV/views.py", line 58, in MainPage
    tg=Tags(text_id=Data.objects.get(Data_xls=request.FILES['Data_xls']).id,tg=i)
  File "/usr/local/lib/python3.5/dist-packages/django/db/models/manager.py", line 122, in manager_method
    return getattr(self.get_queryset(), name)(*args, **kwargs)
  File "/usr/local/lib/python3.5/dist-packages/django/db/models/query.py", line 387, in get
    self.model._meta.object_name
WV.models.DoesNotExist: Data matching query does not exist.
Internal Server Error: /
Traceback (most recent call last):
  File "/usr/local/lib/python3.5/dist-packages/django/core/handlers/base.py", line 149, in get_response
    response = self.process_exception_by_middleware(e, request)
  File "/usr/local/lib/python3.5/dist-packages/django/core/handlers/base.py", line 147, in get_response
    response = wrapped_callback(request, *callback_args, **callback_kwargs)
  File "/opt/WebWord2Vec/WV/views.py", line 53, in MainPage
    form_text.save()
  File "/usr/local/lib/python3.5/dist-packages/django/forms/models.py", line 451, in save
    self.instance.save()
  File "/usr/local/lib/python3.5/dist-packages/django/db/models/base.py", line 700, in save
    force_update=force_update, update_fields=update_fields)
  File "/usr/local/lib/python3.5/dist-packages/django/db/models/base.py", line 728, in save_base
    updated = self._save_table(raw, cls, force_insert, force_update, using, update_fields)
  File "/usr/local/lib/python3.5/dist-packages/django/db/models/base.py", line 812, in _save_table
    result = self._do_insert(cls._base_manager, using, fields, update_pk, raw)
  File "/usr/local/lib/python3.5/dist-packages/django/db/models/base.py", line 851, in _do_insert
    using=using, raw=raw)
  File "/usr/local/lib/python3.5/dist-packages/django/db/models/manager.py", line 122, in manager_method
    return getattr(self.get_queryset(), name)(*args, **kwargs)
  File "/usr/local/lib/python3.5/dist-packages/django/db/models/query.py", line 1039, in _insert
    return query.get_compiler(using=using).execute_sql(return_id)
  File "/usr/local/lib/python3.5/dist-packages/django/db/models/sql/compiler.py", line 1063, in execute_sql
    for sql, params in self.as_sql():
  File "/usr/local/lib/python3.5/dist-packages/django/db/models/sql/compiler.py", line 1023, in as_sql
    for obj in self.query.objs
  File "/usr/local/lib/python3.5/dist-packages/django/db/models/sql/compiler.py", line 1023, in <listcomp>
    for obj in self.query.objs
  File "/usr/local/lib/python3.5/dist-packages/django/db/models/sql/compiler.py", line 1022, in <listcomp>
    [self.prepare_value(field, self.pre_save_val(field, obj)) for field in fields]
  File "/usr/local/lib/python3.5/dist-packages/django/db/models/sql/compiler.py", line 972, in pre_save_val
    return field.pre_save(obj, add=True)
  File "/usr/local/lib/python3.5/dist-packages/django/db/models/fields/files.py", line 311, in pre_save
    file.save(file.name, file, save=False)
  File "/usr/local/lib/python3.5/dist-packages/django/db/models/fields/files.py", line 93, in save
    self.name = self.storage.save(name, content, max_length=self.field.max_length)
  File "/usr/local/lib/python3.5/dist-packages/django/core/files/storage.py", line 63, in save
    name = self._save(name, content)
  File "/usr/local/lib/python3.5/dist-packages/django/core/files/storage.py", line 275, in _save
    os.chmod(full_path, self.file_permissions_mode)
TypeError: an integer is required (got type str)
Internal Server Error: /
Traceback (most recent call last):
  File "/usr/local/lib/python3.5/dist-packages/django/core/handlers/base.py", line 149, in get_response
    response = self.process_exception_by_middleware(e, request)
  File "/usr/local/lib/python3.5/dist-packages/django/core/handlers/base.py", line 147, in get_response
    response = wrapped_callback(request, *callback_args, **callback_kwargs)
  File "/opt/WebWord2Vec/WV/views.py", line 53, in MainPage
    form_text.save()
  File "/usr/local/lib/python3.5/dist-packages/django/forms/models.py", line 451, in save
    self.instance.save()
  File "/usr/local/lib/python3.5/dist-packages/django/db/models/base.py", line 700, in save
    force_update=force_update, update_fields=update_fields)
  File "/usr/local/lib/python3.5/dist-packages/django/db/models/base.py", line 728, in save_base
    updated = self._save_table(raw, cls, force_insert, force_update, using, update_fields)
  File "/usr/local/lib/python3.5/dist-packages/django/db/models/base.py", line 812, in _save_table
    result = self._do_insert(cls._base_manager, using, fields, update_pk, raw)
  File "/usr/local/lib/python3.5/dist-packages/django/db/models/base.py", line 851, in _do_insert
    using=using, raw=raw)
  File "/usr/local/lib/python3.5/dist-packages/django/db/models/manager.py", line 122, in manager_method
    return getattr(self.get_queryset(), name)(*args, **kwargs)
  File "/usr/local/lib/python3.5/dist-packages/django/db/models/query.py", line 1039, in _insert
    return query.get_compiler(using=using).execute_sql(return_id)
  File "/usr/local/lib/python3.5/dist-packages/django/db/models/sql/compiler.py", line 1063, in execute_sql
    for sql, params in self.as_sql():
  File "/usr/local/lib/python3.5/dist-packages/django/db/models/sql/compiler.py", line 1023, in as_sql
    for obj in self.query.objs
  File "/usr/local/lib/python3.5/dist-packages/django/db/models/sql/compiler.py", line 1023, in <listcomp>
    for obj in self.query.objs
  File "/usr/local/lib/python3.5/dist-packages/django/db/models/sql/compiler.py", line 1022, in <listcomp>
    [self.prepare_value(field, self.pre_save_val(field, obj)) for field in fields]
  File "/usr/local/lib/python3.5/dist-packages/django/db/models/sql/compiler.py", line 972, in pre_save_val
    return field.pre_save(obj, add=True)
  File "/usr/local/lib/python3.5/dist-packages/django/db/models/fields/files.py", line 311, in pre_save
    file.save(file.name, file, save=False)
  File "/usr/local/lib/python3.5/dist-packages/django/db/models/fields/files.py", line 93, in save
    self.name = self.storage.save(name, content, max_length=self.field.max_length)
  File "/usr/local/lib/python3.5/dist-packages/django/core/files/storage.py", line 63, in save
    name = self._save(name, content)
  File "/usr/local/lib/python3.5/dist-packages/django/core/files/storage.py", line 275, in _save
    os.chmod(full_path, self.file_permissions_mode)
TypeError: an integer is required (got type str)
Internal Server Error: /
Traceback (most recent call last):
  File "/usr/local/lib/python3.5/dist-packages/django/core/handlers/base.py", line 149, in get_response
    response = self.process_exception_by_middleware(e, request)
  File "/usr/local/lib/python3.5/dist-packages/django/core/handlers/base.py", line 147, in get_response
    response = wrapped_callback(request, *callback_args, **callback_kwargs)
  File "/opt/WebWord2Vec/WV/views.py", line 53, in MainPage
    form_text.save()
  File "/usr/local/lib/python3.5/dist-packages/django/forms/models.py", line 451, in save
    self.instance.save()
  File "/usr/local/lib/python3.5/dist-packages/django/db/models/base.py", line 700, in save
    force_update=force_update, update_fields=update_fields)
  File "/usr/local/lib/python3.5/dist-packages/django/db/models/base.py", line 728, in save_base
    updated = self._save_table(raw, cls, force_insert, force_update, using, update_fields)
  File "/usr/local/lib/python3.5/dist-packages/django/db/models/base.py", line 812, in _save_table
    result = self._do_insert(cls._base_manager, using, fields, update_pk, raw)
  File "/usr/local/lib/python3.5/dist-packages/django/db/models/base.py", line 851, in _do_insert
    using=using, raw=raw)
  File "/usr/local/lib/python3.5/dist-packages/django/db/models/manager.py", line 122, in manager_method
    return getattr(self.get_queryset(), name)(*args, **kwargs)
  File "/usr/local/lib/python3.5/dist-packages/django/db/models/query.py", line 1039, in _insert
    return query.get_compiler(using=using).execute_sql(return_id)
  File "/usr/local/lib/python3.5/dist-packages/django/db/models/sql/compiler.py", line 1063, in execute_sql
    for sql, params in self.as_sql():
  File "/usr/local/lib/python3.5/dist-packages/django/db/models/sql/compiler.py", line 1023, in as_sql
    for obj in self.query.objs
  File "/usr/local/lib/python3.5/dist-packages/django/db/models/sql/compiler.py", line 1023, in <listcomp>
    for obj in self.query.objs
  File "/usr/local/lib/python3.5/dist-packages/django/db/models/sql/compiler.py", line 1022, in <listcomp>
    [self.prepare_value(field, self.pre_save_val(field, obj)) for field in fields]
  File "/usr/local/lib/python3.5/dist-packages/django/db/models/sql/compiler.py", line 972, in pre_save_val
    return field.pre_save(obj, add=True)
  File "/usr/local/lib/python3.5/dist-packages/django/db/models/fields/files.py", line 311, in pre_save
    file.save(file.name, file, save=False)
  File "/usr/local/lib/python3.5/dist-packages/django/db/models/fields/files.py", line 93, in save
    self.name = self.storage.save(name, content, max_length=self.field.max_length)
  File "/usr/local/lib/python3.5/dist-packages/django/core/files/storage.py", line 63, in save
    name = self._save(name, content)
  File "/usr/local/lib/python3.5/dist-packages/django/core/files/storage.py", line 275, in _save
    os.chmod(full_path, self.file_permissions_mode)
TypeError: an integer is required (got type str)
Internal Server Error: /
Traceback (most recent call last):
  File "/usr/local/lib/python3.5/dist-packages/django/core/handlers/base.py", line 149, in get_response
    response = self.process_exception_by_middleware(e, request)
  File "/usr/local/lib/python3.5/dist-packages/django/core/handlers/base.py", line 147, in get_response
    response = wrapped_callback(request, *callback_args, **callback_kwargs)
  File "/opt/WebWord2Vec/WV/views.py", line 58, in MainPage
    tg=Tags(text_id=Data.objects.get(Data_xls=request.FILES['Data_xls']).id,tg=i)
  File "/usr/local/lib/python3.5/dist-packages/django/db/models/manager.py", line 122, in manager_method
    return getattr(self.get_queryset(), name)(*args, **kwargs)
  File "/usr/local/lib/python3.5/dist-packages/django/db/models/query.py", line 387, in get
    self.model._meta.object_name
WV.models.DoesNotExist: Data matching query does not exist.
Internal Server Error: /
Traceback (most recent call last):
  File "/usr/local/lib/python3.5/dist-packages/django/core/handlers/base.py", line 149, in get_response
    response = self.process_exception_by_middleware(e, request)
  File "/usr/local/lib/python3.5/dist-packages/django/core/handlers/base.py", line 147, in get_response
    response = wrapped_callback(request, *callback_args, **callback_kwargs)
  File "/opt/WebWord2Vec/WV/views.py", line 58, in MainPage
    tg=Tags(text_id=Data.objects.get(Data_xls=request.FILES['Data_xls']).id,tg=i)
  File "/usr/local/lib/python3.5/dist-packages/django/db/models/manager.py", line 122, in manager_method
    return getattr(self.get_queryset(), name)(*args, **kwargs)
  File "/usr/local/lib/python3.5/dist-packages/django/db/models/query.py", line 387, in get
    self.model._meta.object_name
WV.models.DoesNotExist: Data matching query does not exist.
Internal Server Error: /
Traceback (most recent call last):
  File "/usr/local/lib/python3.5/dist-packages/django/core/handlers/base.py", line 149, in get_response
    response = self.process_exception_by_middleware(e, request)
  File "/usr/local/lib/python3.5/dist-packages/django/core/handlers/base.py", line 147, in get_response
    response = wrapped_callback(request, *callback_args, **callback_kwargs)
  File "/opt/WebWord2Vec/WV/views.py", line 58, in MainPage
    tg=Tags(text_id=Data.objects.get(Data_xls=request.FILES['Data_xls']).id,tg=i)
  File "/usr/local/lib/python3.5/dist-packages/django/db/models/manager.py", line 122, in manager_method
    return getattr(self.get_queryset(), name)(*args, **kwargs)
  File "/usr/local/lib/python3.5/dist-packages/django/db/models/query.py", line 387, in get
    self.model._meta.object_name
WV.models.DoesNotExist: Data matching query does not exist.
Internal Server Error: /
Traceback (most recent call last):
  File "/usr/local/lib/python3.5/dist-packages/django/core/handlers/base.py", line 149, in get_response
    response = self.process_exception_by_middleware(e, request)
  File "/usr/local/lib/python3.5/dist-packages/django/core/handlers/base.py", line 147, in get_response
    response = wrapped_callback(request, *callback_args, **callback_kwargs)
  File "/opt/WebWord2Vec/WV/views.py", line 56, in MainPage
    ptint(request.FILES['Data_xls'])
NameError: name 'ptint' is not defined
Internal Server Error: /
Traceback (most recent call last):
  File "/usr/local/lib/python3.5/dist-packages/django/core/handlers/base.py", line 149, in get_response
    response = self.process_exception_by_middleware(e, request)
  File "/usr/local/lib/python3.5/dist-packages/django/core/handlers/base.py", line 147, in get_response
    response = wrapped_callback(request, *callback_args, **callback_kwargs)
  File "/opt/WebWord2Vec/WV/views.py", line 58, in MainPage
    tg=Tags(text_id=Data.objects.get(Data_xls=request.FILES['Data_xls']).id,tg=i)
  File "/usr/local/lib/python3.5/dist-packages/django/db/models/manager.py", line 122, in manager_method
    return getattr(self.get_queryset(), name)(*args, **kwargs)
  File "/usr/local/lib/python3.5/dist-packages/django/db/models/query.py", line 387, in get
    self.model._meta.object_name
WV.models.DoesNotExist: Data matching query does not exist.
Internal Server Error: /
Traceback (most recent call last):
  File "/usr/local/lib/python3.5/dist-packages/django/core/handlers/base.py", line 149, in get_response
    response = self.process_exception_by_middleware(e, request)
  File "/usr/local/lib/python3.5/dist-packages/django/core/handlers/base.py", line 147, in get_response
    response = wrapped_callback(request, *callback_args, **callback_kwargs)
  File "/opt/WebWord2Vec/WV/views.py", line 58, in MainPage
    tg=Tags(text_id=Data.objects.get(Data_xls=os.path.join(MEDIA_ROOT,request.FILES['Data_xls'])).id,tg=i)
  File "/usr/lib/python3.5/posixpath.py", line 89, in join
    genericpath._check_arg_types('join', a, *p)
  File "/usr/lib/python3.5/genericpath.py", line 143, in _check_arg_types
    (funcname, s.__class__.__name__)) from None
TypeError: join() argument must be str or bytes, not 'InMemoryUploadedFile'
Internal Server Error: /
Traceback (most recent call last):
  File "/usr/local/lib/python3.5/dist-packages/django/core/handlers/base.py", line 134, in get_response
    resolver_match = resolver.resolve(request.path_info)
  File "/usr/local/lib/python3.5/dist-packages/django/core/urlresolvers.py", line 374, in resolve
    for pattern in self.url_patterns:
  File "/usr/local/lib/python3.5/dist-packages/django/utils/functional.py", line 33, in __get__
    res = instance.__dict__[self.name] = self.func(instance)
  File "/usr/local/lib/python3.5/dist-packages/django/core/urlresolvers.py", line 417, in url_patterns
    patterns = getattr(self.urlconf_module, "urlpatterns", self.urlconf_module)
  File "/usr/local/lib/python3.5/dist-packages/django/utils/functional.py", line 33, in __get__
    res = instance.__dict__[self.name] = self.func(instance)
  File "/usr/local/lib/python3.5/dist-packages/django/core/urlresolvers.py", line 410, in urlconf_module
    return import_module(self.urlconf_name)
  File "/usr/lib/python3.5/importlib/__init__.py", line 126, in import_module
    return _bootstrap._gcd_import(name[level:], package, level)
  File "<frozen importlib._bootstrap>", line 986, in _gcd_import
  File "<frozen importlib._bootstrap>", line 969, in _find_and_load
  File "<frozen importlib._bootstrap>", line 958, in _find_and_load_unlocked
  File "<frozen importlib._bootstrap>", line 673, in _load_unlocked
  File "<frozen importlib._bootstrap_external>", line 665, in exec_module
  File "<frozen importlib._bootstrap>", line 222, in _call_with_frames_removed
  File "/opt/WebWord2Vec/Word2Vec/urls.py", line 23, in <module>
    url(r'^', include('WV.urls')),
  File "/usr/local/lib/python3.5/dist-packages/django/conf/urls/__init__.py", line 52, in include
    urlconf_module = import_module(urlconf_module)
  File "/usr/lib/python3.5/importlib/__init__.py", line 126, in import_module
    return _bootstrap._gcd_import(name[level:], package, level)
  File "<frozen importlib._bootstrap>", line 986, in _gcd_import
  File "<frozen importlib._bootstrap>", line 969, in _find_and_load
  File "<frozen importlib._bootstrap>", line 958, in _find_and_load_unlocked
  File "<frozen importlib._bootstrap>", line 673, in _load_unlocked
  File "<frozen importlib._bootstrap_external>", line 665, in exec_module
  File "<frozen importlib._bootstrap>", line 222, in _call_with_frames_removed
  File "/opt/WebWord2Vec/WV/urls.py", line 2, in <module>
    from WV import views
  File "/opt/WebWord2Vec/WV/views.py", line 58
    tg=Tags(text_id=Data.objects.get(Data_xls=os.path.join(MEDIA_ROOT,str(request.FILES['Data_xls'])))).id,tg=i)
                                                                                                               ^
SyntaxError: invalid syntax
Internal Server Error: /
Traceback (most recent call last):
  File "/usr/local/lib/python3.5/dist-packages/django/core/handlers/base.py", line 134, in get_response
    resolver_match = resolver.resolve(request.path_info)
  File "/usr/local/lib/python3.5/dist-packages/django/core/urlresolvers.py", line 374, in resolve
    for pattern in self.url_patterns:
  File "/usr/local/lib/python3.5/dist-packages/django/utils/functional.py", line 33, in __get__
    res = instance.__dict__[self.name] = self.func(instance)
  File "/usr/local/lib/python3.5/dist-packages/django/core/urlresolvers.py", line 417, in url_patterns
    patterns = getattr(self.urlconf_module, "urlpatterns", self.urlconf_module)
  File "/usr/local/lib/python3.5/dist-packages/django/utils/functional.py", line 33, in __get__
    res = instance.__dict__[self.name] = self.func(instance)
  File "/usr/local/lib/python3.5/dist-packages/django/core/urlresolvers.py", line 410, in urlconf_module
    return import_module(self.urlconf_name)
  File "/usr/lib/python3.5/importlib/__init__.py", line 126, in import_module
    return _bootstrap._gcd_import(name[level:], package, level)
  File "<frozen importlib._bootstrap>", line 986, in _gcd_import
  File "<frozen importlib._bootstrap>", line 969, in _find_and_load
  File "<frozen importlib._bootstrap>", line 958, in _find_and_load_unlocked
  File "<frozen importlib._bootstrap>", line 673, in _load_unlocked
  File "<frozen importlib._bootstrap_external>", line 665, in exec_module
  File "<frozen importlib._bootstrap>", line 222, in _call_with_frames_removed
  File "/opt/WebWord2Vec/Word2Vec/urls.py", line 23, in <module>
    url(r'^', include('WV.urls')),
  File "/usr/local/lib/python3.5/dist-packages/django/conf/urls/__init__.py", line 52, in include
    urlconf_module = import_module(urlconf_module)
  File "/usr/lib/python3.5/importlib/__init__.py", line 126, in import_module
    return _bootstrap._gcd_import(name[level:], package, level)
  File "<frozen importlib._bootstrap>", line 986, in _gcd_import
  File "<frozen importlib._bootstrap>", line 969, in _find_and_load
  File "<frozen importlib._bootstrap>", line 958, in _find_and_load_unlocked
  File "<frozen importlib._bootstrap>", line 673, in _load_unlocked
  File "<frozen importlib._bootstrap_external>", line 665, in exec_module
  File "<frozen importlib._bootstrap>", line 222, in _call_with_frames_removed
  File "/opt/WebWord2Vec/WV/urls.py", line 2, in <module>
    from WV import views
  File "/opt/WebWord2Vec/WV/views.py", line 58
    tg=Tags(text_id=Data.objects.get(Data_xls=os.path.join(MEDIA_ROOT,str(request.FILES['Data_xls'])))).id,tg=i)
                                                                                                               ^
SyntaxError: invalid syntax
Internal Server Error: /
Traceback (most recent call last):
  File "/usr/local/lib/python3.5/dist-packages/django/core/handlers/base.py", line 149, in get_response
    response = self.process_exception_by_middleware(e, request)
  File "/usr/local/lib/python3.5/dist-packages/django/core/handlers/base.py", line 147, in get_response
    response = wrapped_callback(request, *callback_args, **callback_kwargs)
  File "/opt/WebWord2Vec/WV/views.py", line 58, in MainPage
    tg=Tags(text_id=Data.objects.get(Data_xls=os.path.join(MEDIA_ROOT,str(request.FILES['Data_xls']))).id,tg=i)
  File "/usr/local/lib/python3.5/dist-packages/django/db/models/manager.py", line 122, in manager_method
    return getattr(self.get_queryset(), name)(*args, **kwargs)
  File "/usr/local/lib/python3.5/dist-packages/django/db/models/query.py", line 387, in get
    self.model._meta.object_name
WV.models.DoesNotExist: Data matching query does not exist.
Internal Server Error: /
Traceback (most recent call last):
  File "/usr/local/lib/python3.5/dist-packages/django/core/handlers/base.py", line 149, in get_response
    response = self.process_exception_by_middleware(e, request)
  File "/usr/local/lib/python3.5/dist-packages/django/core/handlers/base.py", line 147, in get_response
    response = wrapped_callback(request, *callback_args, **callback_kwargs)
  File "/opt/WebWord2Vec/WV/views.py", line 56, in MainPage
    print(Data.objects.get(Data_xls.FILES['Data_xls']).id)
NameError: name 'Data_xls' is not defined
Internal Server Error: /
Traceback (most recent call last):
  File "/usr/local/lib/python3.5/dist-packages/django/core/handlers/base.py", line 149, in get_response
    response = self.process_exception_by_middleware(e, request)
  File "/usr/local/lib/python3.5/dist-packages/django/core/handlers/base.py", line 147, in get_response
    response = wrapped_callback(request, *callback_args, **callback_kwargs)
  File "/opt/WebWord2Vec/WV/views.py", line 56, in MainPage
    print(Data.objects.get(Data_xls=request.FILES['Data_xls']).id)
  File "/usr/local/lib/python3.5/dist-packages/django/db/models/manager.py", line 122, in manager_method
    return getattr(self.get_queryset(), name)(*args, **kwargs)
  File "/usr/local/lib/python3.5/dist-packages/django/db/models/query.py", line 387, in get
    self.model._meta.object_name
WV.models.DoesNotExist: Data matching query does not exist.
Internal Server Error: /
Traceback (most recent call last):
  File "/usr/local/lib/python3.5/dist-packages/django/core/handlers/base.py", line 149, in get_response
    response = self.process_exception_by_middleware(e, request)
  File "/usr/local/lib/python3.5/dist-packages/django/core/handlers/base.py", line 147, in get_response
    response = wrapped_callback(request, *callback_args, **callback_kwargs)
  File "/opt/WebWord2Vec/WV/views.py", line 56, in MainPage
    print(Data.objects.get(id=350).Data_xls)
  File "/usr/local/lib/python3.5/dist-packages/django/db/models/manager.py", line 122, in manager_method
    return getattr(self.get_queryset(), name)(*args, **kwargs)
  File "/usr/local/lib/python3.5/dist-packages/django/db/models/query.py", line 387, in get
    self.model._meta.object_name
WV.models.DoesNotExist: Data matching query does not exist.
Internal Server Error: /
Traceback (most recent call last):
  File "/usr/local/lib/python3.5/dist-packages/django/core/handlers/base.py", line 149, in get_response
    response = self.process_exception_by_middleware(e, request)
  File "/usr/local/lib/python3.5/dist-packages/django/core/handlers/base.py", line 147, in get_response
    response = wrapped_callback(request, *callback_args, **callback_kwargs)
  File "/opt/WebWord2Vec/WV/views.py", line 58, in MainPage
    tg=Tags(text_id=Data.objects.get(Data_xls=request.FILES['Data_xls']).id,tg=i)
  File "/usr/local/lib/python3.5/dist-packages/django/db/models/manager.py", line 122, in manager_method
    return getattr(self.get_queryset(), name)(*args, **kwargs)
  File "/usr/local/lib/python3.5/dist-packages/django/db/models/query.py", line 387, in get
    self.model._meta.object_name
WV.models.DoesNotExist: Data matching query does not exist.
Internal Server Error: /
Traceback (most recent call last):
  File "/usr/local/lib/python3.5/dist-packages/django/core/handlers/base.py", line 149, in get_response
    response = self.process_exception_by_middleware(e, request)
  File "/usr/local/lib/python3.5/dist-packages/django/core/handlers/base.py", line 147, in get_response
    response = wrapped_callback(request, *callback_args, **callback_kwargs)
  File "/opt/WebWord2Vec/WV/views.py", line 58, in MainPage
    tg=Tags(text_id=Data.objects.get(Data_xls=request.FILES['Data_xls']).id,tg=i)
  File "/usr/local/lib/python3.5/dist-packages/django/db/models/manager.py", line 122, in manager_method
    return getattr(self.get_queryset(), name)(*args, **kwargs)
  File "/usr/local/lib/python3.5/dist-packages/django/db/models/query.py", line 387, in get
    self.model._meta.object_name
WV.models.DoesNotExist: Data matching query does not exist.
Internal Server Error: /
Traceback (most recent call last):
  File "/usr/local/lib/python3.5/dist-packages/django/core/handlers/base.py", line 149, in get_response
    response = self.process_exception_by_middleware(e, request)
  File "/usr/local/lib/python3.5/dist-packages/django/core/handlers/base.py", line 147, in get_response
    response = wrapped_callback(request, *callback_args, **callback_kwargs)
  File "/opt/WebWord2Vec/WV/views.py", line 59, in MainPage
    tg=Tags(text_id=Data.objects.get(Data_xls=request.FILES['Data_xls']).id,tg=i)
  File "/usr/local/lib/python3.5/dist-packages/django/db/models/manager.py", line 122, in manager_method
    return getattr(self.get_queryset(), name)(*args, **kwargs)
  File "/usr/local/lib/python3.5/dist-packages/django/db/models/query.py", line 387, in get
    self.model._meta.object_name
WV.models.DoesNotExist: Data matching query does not exist.
Internal Server Error: /
Traceback (most recent call last):
  File "/usr/local/lib/python3.5/dist-packages/django/core/handlers/base.py", line 149, in get_response
    response = self.process_exception_by_middleware(e, request)
  File "/usr/local/lib/python3.5/dist-packages/django/core/handlers/base.py", line 147, in get_response
    response = wrapped_callback(request, *callback_args, **callback_kwargs)
  File "/opt/WebWord2Vec/WV/views.py", line 57, in MainPage
    tg=Tags(text_id=Data.objects.get(Data_xls=request.FILES['Data_xls'].name).id,tg=i)
  File "/usr/local/lib/python3.5/dist-packages/django/db/models/manager.py", line 122, in manager_method
    return getattr(self.get_queryset(), name)(*args, **kwargs)
  File "/usr/local/lib/python3.5/dist-packages/django/db/models/query.py", line 387, in get
    self.model._meta.object_name
WV.models.DoesNotExist: Data matching query does not exist.
Internal Server Error: /
Traceback (most recent call last):
  File "/usr/local/lib/python3.5/dist-packages/django/core/handlers/base.py", line 149, in get_response
    response = self.process_exception_by_middleware(e, request)
  File "/usr/local/lib/python3.5/dist-packages/django/core/handlers/base.py", line 147, in get_response
    response = wrapped_callback(request, *callback_args, **callback_kwargs)
  File "/opt/WebWord2Vec/WV/views.py", line 60, in MainPage
    tg=Tags(text_id=Data.objects.get(Data_xls=request.FILES['Data_xls']).id,tg=i)
  File "/usr/local/lib/python3.5/dist-packages/django/db/models/manager.py", line 122, in manager_method
    return getattr(self.get_queryset(), name)(*args, **kwargs)
  File "/usr/local/lib/python3.5/dist-packages/django/db/models/query.py", line 387, in get
    self.model._meta.object_name
WV.models.DoesNotExist: Data matching query does not exist.
Internal Server Error: /
Traceback (most recent call last):
  File "/usr/local/lib/python3.5/dist-packages/django/core/handlers/base.py", line 149, in get_response
    response = self.process_exception_by_middleware(e, request)
  File "/usr/local/lib/python3.5/dist-packages/django/core/handlers/base.py", line 147, in get_response
    response = wrapped_callback(request, *callback_args, **callback_kwargs)
  File "/opt/WebWord2Vec/WV/views.py", line 60, in MainPage
    tg=Tags(text_id=Data.objects.get(Data_xls=request.FILES['Data_xls']).id,tg=i)
  File "/usr/local/lib/python3.5/dist-packages/django/db/models/manager.py", line 122, in manager_method
    return getattr(self.get_queryset(), name)(*args, **kwargs)
  File "/usr/local/lib/python3.5/dist-packages/django/db/models/query.py", line 387, in get
    self.model._meta.object_name
WV.models.DoesNotExist: Data matching query does not exist.
Internal Server Error: /
Traceback (most recent call last):
  File "/usr/local/lib/python3.5/dist-packages/django/core/handlers/base.py", line 149, in get_response
    response = self.process_exception_by_middleware(e, request)
  File "/usr/local/lib/python3.5/dist-packages/django/core/handlers/base.py", line 147, in get_response
    response = wrapped_callback(request, *callback_args, **callback_kwargs)
  File "/opt/WebWord2Vec/WV/views.py", line 60, in MainPage
    tg=Tags(text_id=Data.objects.get(Data_xls=request.FILES['Data_xls']).id,tg=i)
  File "/usr/local/lib/python3.5/dist-packages/django/db/models/manager.py", line 122, in manager_method
    return getattr(self.get_queryset(), name)(*args, **kwargs)
  File "/usr/local/lib/python3.5/dist-packages/django/db/models/query.py", line 387, in get
    self.model._meta.object_name
WV.models.DoesNotExist: Data matching query does not exist.
Internal Server Error: /options/308/
Traceback (most recent call last):
  File "/usr/local/lib/python3.5/dist-packages/django/core/handlers/base.py", line 149, in get_response
    response = self.process_exception_by_middleware(e, request)
  File "/usr/local/lib/python3.5/dist-packages/django/core/handlers/base.py", line 147, in get_response
    response = wrapped_callback(request, *callback_args, **callback_kwargs)
  File "/opt/WebWord2Vec/WV/views.py", line 251, in Enteroptions
    int(request.POST['size']), int(request.POST['win']),
  File "/opt/WebWord2Vec/WV/views.py", line 246, in Map
    # BuildWordMap()
  File "/opt/WebWord2Vec/WV/views.py", line 218, in BuildHtmlMap
    options.img=picture_name
OSError: [Errno 5] Input/output error
Internal Server Error: /options/312/
Traceback (most recent call last):
  File "/usr/local/lib/python3.5/dist-packages/django/core/handlers/base.py", line 149, in get_response
    response = self.process_exception_by_middleware(e, request)
  File "/usr/local/lib/python3.5/dist-packages/django/core/handlers/base.py", line 147, in get_response
    response = wrapped_callback(request, *callback_args, **callback_kwargs)
  File "/opt/WebWord2Vec/WV/views.py", line 251, in Enteroptions
    int(request.POST['size']), int(request.POST['win']),
  File "/opt/WebWord2Vec/WV/views.py", line 246, in Map
    # BuildWordMap()
  File "/opt/WebWord2Vec/WV/views.py", line 218, in BuildHtmlMap
    options.img=picture_name
OSError: [Errno 5] Input/output error
Internal Server Error: /options/313/
Traceback (most recent call last):
  File "/usr/local/lib/python3.5/dist-packages/django/core/handlers/base.py", line 149, in get_response
    response = self.process_exception_by_middleware(e, request)
  File "/usr/local/lib/python3.5/dist-packages/django/core/handlers/base.py", line 147, in get_response
    response = wrapped_callback(request, *callback_args, **callback_kwargs)
  File "/opt/WebWord2Vec/WV/views.py", line 251, in Enteroptions
    int(request.POST['size']), int(request.POST['win']),
  File "/opt/WebWord2Vec/WV/views.py", line 246, in Map
    # BuildWordMap()
  File "/opt/WebWord2Vec/WV/views.py", line 218, in BuildHtmlMap
    options.img=picture_name
OSError: [Errno 5] Input/output error
Internal Server Error: /options/313/
Traceback (most recent call last):
  File "/usr/local/lib/python3.5/dist-packages/django/core/handlers/base.py", line 149, in get_response
    response = self.process_exception_by_middleware(e, request)
  File "/usr/local/lib/python3.5/dist-packages/django/core/handlers/base.py", line 147, in get_response
    response = wrapped_callback(request, *callback_args, **callback_kwargs)
  File "/opt/WebWord2Vec/WV/views.py", line 251, in Enteroptions
    int(request.POST['size']), int(request.POST['win']),
  File "/opt/WebWord2Vec/WV/views.py", line 246, in Map
    # BuildWordMap()
  File "/opt/WebWord2Vec/WV/views.py", line 218, in BuildHtmlMap
    options.img=picture_name
OSError: [Errno 5] Input/output error
Internal Server Error: /options/313/
Traceback (most recent call last):
  File "/usr/local/lib/python3.5/dist-packages/django/core/handlers/base.py", line 149, in get_response
    response = self.process_exception_by_middleware(e, request)
  File "/usr/local/lib/python3.5/dist-packages/django/core/handlers/base.py", line 147, in get_response
    response = wrapped_callback(request, *callback_args, **callback_kwargs)
  File "/opt/WebWord2Vec/WV/views.py", line 251, in Enteroptions
    int(request.POST['size']), int(request.POST['win']),
  File "/opt/WebWord2Vec/WV/views.py", line 246, in Map
    # BuildWordMap()
  File "/opt/WebWord2Vec/WV/views.py", line 218, in BuildHtmlMap
    options.img=picture_name
OSError: [Errno 5] Input/output error
Internal Server Error: /options/313/
Traceback (most recent call last):
  File "/usr/local/lib/python3.5/dist-packages/django/core/handlers/base.py", line 149, in get_response
    response = self.process_exception_by_middleware(e, request)
  File "/usr/local/lib/python3.5/dist-packages/django/core/handlers/base.py", line 147, in get_response
    response = wrapped_callback(request, *callback_args, **callback_kwargs)
  File "/opt/WebWord2Vec/WV/views.py", line 251, in Enteroptions
    int(request.POST['minc'])))
  File "/opt/WebWord2Vec/WV/views.py", line 246, in Map
    BuildHtmlMap()
  File "/opt/WebWord2Vec/WV/views.py", line 218, in BuildHtmlMap
    options.img = picture_name
OSError: [Errno 5] Input/output error
Internal Server Error: /options/312/
Traceback (most recent call last):
  File "/usr/local/lib/python3.5/dist-packages/django/core/handlers/base.py", line 149, in get_response
    response = self.process_exception_by_middleware(e, request)
  File "/usr/local/lib/python3.5/dist-packages/django/core/handlers/base.py", line 147, in get_response
    response = wrapped_callback(request, *callback_args, **callback_kwargs)
  File "/opt/WebWord2Vec/WV/views.py", line 251, in Enteroptions
    int(request.POST['minc'])))
  File "/opt/WebWord2Vec/WV/views.py", line 246, in Map
    BuildHtmlMap()
  File "/opt/WebWord2Vec/WV/views.py", line 218, in BuildHtmlMap
    options.img = picture_name
OSError: [Errno 5] Input/output error
Internal Server Error: /
Traceback (most recent call last):
  File "/usr/local/lib/python3.5/dist-packages/django/core/handlers/base.py", line 149, in get_response
    response = self.process_exception_by_middleware(e, request)
  File "/usr/local/lib/python3.5/dist-packages/django/core/handlers/base.py", line 147, in get_response
    response = wrapped_callback(request, *callback_args, **callback_kwargs)
  File "/opt/WebWord2Vec/WV/views.py", line 51, in MainPage
    if  form_text.is_valid() and form_tg.is_valid() :
  File "/opt/WebWord2Vec/WV/forms.py", line 40, in is_valid
    valid = super(EnterData, self).is_valid()
  File "/usr/local/lib/python3.5/dist-packages/django/forms/forms.py", line 161, in is_valid
    return self.is_bound and not self.errors
  File "/usr/local/lib/python3.5/dist-packages/django/forms/forms.py", line 153, in errors
    self.full_clean()
  File "/usr/local/lib/python3.5/dist-packages/django/forms/forms.py", line 363, in full_clean
    self._clean_form()
  File "/usr/local/lib/python3.5/dist-packages/django/forms/forms.py", line 390, in _clean_form
    cleaned_data = self.clean()
  File "/opt/WebWord2Vec/WV/forms.py", line 34, in clean
    cleaned_data['Data_xls'].name=ChangeName(filename= cleaned_data['Data_xls'].name)
  File "/opt/WebWord2Vec/WV/forms.py", line 31, in ChangeName
    print(filename)            # return the whole path to the file
OSError: [Errno 5] Input/output error
Internal Server Error: /
Traceback (most recent call last):
  File "/usr/local/lib/python3.5/dist-packages/django/core/handlers/base.py", line 149, in get_response
    response = self.process_exception_by_middleware(e, request)
  File "/usr/local/lib/python3.5/dist-packages/django/core/handlers/base.py", line 147, in get_response
    response = wrapped_callback(request, *callback_args, **callback_kwargs)
  File "/opt/WebWord2Vec/WV/views.py", line 51, in MainPage
    if  form_text.is_valid() and form_tg.is_valid() :
  File "/opt/WebWord2Vec/WV/forms.py", line 40, in is_valid
    valid = super(EnterData, self).is_valid()
  File "/usr/local/lib/python3.5/dist-packages/django/forms/forms.py", line 161, in is_valid
    return self.is_bound and not self.errors
  File "/usr/local/lib/python3.5/dist-packages/django/forms/forms.py", line 153, in errors
    self.full_clean()
  File "/usr/local/lib/python3.5/dist-packages/django/forms/forms.py", line 363, in full_clean
    self._clean_form()
  File "/usr/local/lib/python3.5/dist-packages/django/forms/forms.py", line 390, in _clean_form
    cleaned_data = self.clean()
  File "/opt/WebWord2Vec/WV/forms.py", line 34, in clean
    cleaned_data['Data_xls'].name=ChangeName(filename= cleaned_data['Data_xls'].name)
  File "/opt/WebWord2Vec/WV/forms.py", line 31, in ChangeName
    print(filename)            # return the whole path to the file
OSError: [Errno 5] Input/output error
Internal Server Error: /
Traceback (most recent call last):
  File "/usr/local/lib/python3.5/dist-packages/django/core/handlers/base.py", line 149, in get_response
    response = self.process_exception_by_middleware(e, request)
  File "/usr/local/lib/python3.5/dist-packages/django/core/handlers/base.py", line 147, in get_response
    response = wrapped_callback(request, *callback_args, **callback_kwargs)
  File "/opt/WebWord2Vec/WV/views.py", line 51, in MainPage
    if  form_text.is_valid() and form_tg.is_valid() :
  File "/opt/WebWord2Vec/WV/forms.py", line 40, in is_valid
    valid = super(EnterData, self).is_valid()
  File "/usr/local/lib/python3.5/dist-packages/django/forms/forms.py", line 161, in is_valid
    return self.is_bound and not self.errors
  File "/usr/local/lib/python3.5/dist-packages/django/forms/forms.py", line 153, in errors
    self.full_clean()
  File "/usr/local/lib/python3.5/dist-packages/django/forms/forms.py", line 363, in full_clean
    self._clean_form()
  File "/usr/local/lib/python3.5/dist-packages/django/forms/forms.py", line 390, in _clean_form
    cleaned_data = self.clean()
  File "/opt/WebWord2Vec/WV/forms.py", line 34, in clean
    cleaned_data['Data_xls'].name=ChangeName(filename= cleaned_data['Data_xls'].name)
  File "/opt/WebWord2Vec/WV/forms.py", line 31, in ChangeName
    print(filename)            # return the whole path to the file
OSError: [Errno 5] Input/output error
Internal Server Error: /downloadedtexts/1/
Traceback (most recent call last):
  File "/usr/local/lib/python3.5/dist-packages/django/core/handlers/base.py", line 149, in get_response
    response = self.process_exception_by_middleware(e, request)
  File "/usr/local/lib/python3.5/dist-packages/django/core/handlers/base.py", line 147, in get_response
    response = wrapped_callback(request, *callback_args, **callback_kwargs)
  File "/opt/WebWord2Vec/WV/views.py", line 282, in DownloadedTexts
    print(request.POST['tg'])
OSError: [Errno 5] Input/output error
Internal Server Error: /options/313/
Traceback (most recent call last):
  File "/usr/local/lib/python3.5/dist-packages/django/core/handlers/base.py", line 149, in get_response
    response = self.process_exception_by_middleware(e, request)
  File "/usr/local/lib/python3.5/dist-packages/django/core/handlers/base.py", line 147, in get_response
    response = wrapped_callback(request, *callback_args, **callback_kwargs)
  File "/opt/WebWord2Vec/WV/views.py", line 251, in Enteroptions
    args['form'] = EnterOptions
  File "/opt/WebWord2Vec/WV/views.py", line 246, in Map
    #переделать на ajax
  File "/opt/WebWord2Vec/WV/views.py", line 218, in BuildHtmlMap
    options.script=script
OSError: [Errno 5] Input/output error
Internal Server Error: /downloadedtexts/1/
Traceback (most recent call last):
  File "/usr/local/lib/python3.5/dist-packages/django/core/handlers/base.py", line 149, in get_response
    response = self.process_exception_by_middleware(e, request)
  File "/usr/local/lib/python3.5/dist-packages/django/core/handlers/base.py", line 147, in get_response
    response = wrapped_callback(request, *callback_args, **callback_kwargs)
  File "/opt/WebWord2Vec/WV/views.py", line 282, in DownloadedTexts
    all_texts = Data.objects.all().order_by('-id')
OSError: [Errno 5] Input/output error
Internal Server Error: /options/313/
Traceback (most recent call last):
  File "/usr/local/lib/python3.5/dist-packages/django/core/handlers/base.py", line 149, in get_response
    response = self.process_exception_by_middleware(e, request)
  File "/usr/local/lib/python3.5/dist-packages/django/core/handlers/base.py", line 147, in get_response
    response = wrapped_callback(request, *callback_args, **callback_kwargs)
  File "/opt/WebWord2Vec/WV/views.py", line 251, in Enteroptions
    args['form'] = EnterOptions
  File "/opt/WebWord2Vec/WV/views.py", line 246, in Map
    #переделать на ajax
  File "/opt/WebWord2Vec/WV/views.py", line 218, in BuildHtmlMap
    options.script=script
OSError: [Errno 5] Input/output error
Internal Server Error: /options/313/
Traceback (most recent call last):
  File "/usr/local/lib/python3.5/dist-packages/django/core/handlers/base.py", line 149, in get_response
    response = self.process_exception_by_middleware(e, request)
  File "/usr/local/lib/python3.5/dist-packages/django/core/handlers/base.py", line 147, in get_response
    response = wrapped_callback(request, *callback_args, **callback_kwargs)
  File "/opt/WebWord2Vec/WV/views.py", line 251, in Enteroptions
    args['form'] = EnterOptions
  File "/opt/WebWord2Vec/WV/views.py", line 246, in Map
    #переделать на ajax
  File "/opt/WebWord2Vec/WV/views.py", line 218, in BuildHtmlMap
    options.script=script
OSError: [Errno 5] Input/output error
Internal Server Error: /options/313/
Traceback (most recent call last):
  File "/usr/local/lib/python3.5/dist-packages/django/core/handlers/base.py", line 149, in get_response
    response = self.process_exception_by_middleware(e, request)
  File "/usr/local/lib/python3.5/dist-packages/django/core/handlers/base.py", line 147, in get_response
    response = wrapped_callback(request, *callback_args, **callback_kwargs)
  File "/opt/WebWord2Vec/WV/views.py", line 251, in Enteroptions
    args['form'] = EnterOptions
  File "/opt/WebWord2Vec/WV/views.py", line 246, in Map
    #переделать на ajax
  File "/opt/WebWord2Vec/WV/views.py", line 218, in BuildHtmlMap
    options.script=script
OSError: [Errno 5] Input/output error
Internal Server Error: /
Traceback (most recent call last):
  File "/usr/local/lib/python3.5/dist-packages/django/core/handlers/base.py", line 149, in get_response
    response = self.process_exception_by_middleware(e, request)
  File "/usr/local/lib/python3.5/dist-packages/django/core/handlers/base.py", line 147, in get_response
    response = wrapped_callback(request, *callback_args, **callback_kwargs)
  File "/opt/WebWord2Vec/WV/views.py", line 51, in MainPage
    if  form_text.is_valid() and form_tg.is_valid() :
  File "/opt/WebWord2Vec/WV/forms.py", line 40, in is_valid
    # we're done now if not valid
  File "/usr/local/lib/python3.5/dist-packages/django/forms/forms.py", line 161, in is_valid
    return self.is_bound and not self.errors
  File "/usr/local/lib/python3.5/dist-packages/django/forms/forms.py", line 153, in errors
    self.full_clean()
  File "/usr/local/lib/python3.5/dist-packages/django/forms/forms.py", line 363, in full_clean
    self._clean_form()
  File "/usr/local/lib/python3.5/dist-packages/django/forms/forms.py", line 390, in _clean_form
    cleaned_data = self.clean()
  File "/opt/WebWord2Vec/WV/forms.py", line 34, in clean
  File "/opt/WebWord2Vec/WV/forms.py", line 31, in ChangeName
    return filename
OSError: [Errno 5] Input/output error
Internal Server Error: /
Traceback (most recent call last):
  File "/usr/local/lib/python3.5/dist-packages/django/core/handlers/base.py", line 149, in get_response
    response = self.process_exception_by_middleware(e, request)
  File "/usr/local/lib/python3.5/dist-packages/django/core/handlers/base.py", line 147, in get_response
    response = wrapped_callback(request, *callback_args, **callback_kwargs)
  File "/opt/WebWord2Vec/WV/views.py", line 51, in MainPage
    if  form_text.is_valid() and form_tg.is_valid() :
  File "/opt/WebWord2Vec/WV/forms.py", line 40, in is_valid
    # we're done now if not valid
  File "/usr/local/lib/python3.5/dist-packages/django/forms/forms.py", line 161, in is_valid
    return self.is_bound and not self.errors
  File "/usr/local/lib/python3.5/dist-packages/django/forms/forms.py", line 153, in errors
    self.full_clean()
  File "/usr/local/lib/python3.5/dist-packages/django/forms/forms.py", line 363, in full_clean
    self._clean_form()
  File "/usr/local/lib/python3.5/dist-packages/django/forms/forms.py", line 390, in _clean_form
    cleaned_data = self.clean()
  File "/opt/WebWord2Vec/WV/forms.py", line 34, in clean
  File "/opt/WebWord2Vec/WV/forms.py", line 31, in ChangeName
    return filename
OSError: [Errno 5] Input/output error
Internal Server Error: /
Traceback (most recent call last):
  File "/usr/local/lib/python3.5/dist-packages/django/core/handlers/base.py", line 149, in get_response
    response = self.process_exception_by_middleware(e, request)
  File "/usr/local/lib/python3.5/dist-packages/django/core/handlers/base.py", line 147, in get_response
    response = wrapped_callback(request, *callback_args, **callback_kwargs)
  File "/opt/WebWord2Vec/WV/views.py", line 51, in MainPage
    if  form_text.is_valid() and form_tg.is_valid() :
  File "/opt/WebWord2Vec/WV/forms.py", line 40, in is_valid
    # we're done now if not valid
  File "/usr/local/lib/python3.5/dist-packages/django/forms/forms.py", line 161, in is_valid
    return self.is_bound and not self.errors
  File "/usr/local/lib/python3.5/dist-packages/django/forms/forms.py", line 153, in errors
    self.full_clean()
  File "/usr/local/lib/python3.5/dist-packages/django/forms/forms.py", line 363, in full_clean
    self._clean_form()
  File "/usr/local/lib/python3.5/dist-packages/django/forms/forms.py", line 390, in _clean_form
    cleaned_data = self.clean()
  File "/opt/WebWord2Vec/WV/forms.py", line 34, in clean
  File "/opt/WebWord2Vec/WV/forms.py", line 31, in ChangeName
    return filename
OSError: [Errno 5] Input/output error
Internal Server Error: /options/314/
Traceback (most recent call last):
  File "/usr/local/lib/python3.5/dist-packages/django/core/handlers/base.py", line 149, in get_response
    response = self.process_exception_by_middleware(e, request)
  File "/usr/local/lib/python3.5/dist-packages/django/core/handlers/base.py", line 147, in get_response
    response = wrapped_callback(request, *callback_args, **callback_kwargs)
  File "/opt/WebWord2Vec/WV/views.py", line 251, in Enteroptions
    args['form'] = EnterOptions
  File "/opt/WebWord2Vec/WV/views.py", line 246, in Map
    #переделать на ajax
  File "/opt/WebWord2Vec/WV/views.py", line 218, in BuildHtmlMap
    options.script=script
OSError: [Errno 5] Input/output error
Internal Server Error: /
Traceback (most recent call last):
  File "/usr/local/lib/python3.5/dist-packages/django/core/handlers/base.py", line 149, in get_response
    response = self.process_exception_by_middleware(e, request)
  File "/usr/local/lib/python3.5/dist-packages/django/core/handlers/base.py", line 147, in get_response
    response = wrapped_callback(request, *callback_args, **callback_kwargs)
  File "/opt/WebWord2Vec/WV/views.py", line 51, in MainPage
    if  form_text.is_valid() and form_tg.is_valid() :
  File "/opt/WebWord2Vec/WV/forms.py", line 40, in is_valid
    # we're done now if not valid
  File "/usr/local/lib/python3.5/dist-packages/django/forms/forms.py", line 161, in is_valid
    return self.is_bound and not self.errors
  File "/usr/local/lib/python3.5/dist-packages/django/forms/forms.py", line 153, in errors
    self.full_clean()
  File "/usr/local/lib/python3.5/dist-packages/django/forms/forms.py", line 363, in full_clean
    self._clean_form()
  File "/usr/local/lib/python3.5/dist-packages/django/forms/forms.py", line 390, in _clean_form
    cleaned_data = self.clean()
  File "/opt/WebWord2Vec/WV/forms.py", line 34, in clean
  File "/opt/WebWord2Vec/WV/forms.py", line 31, in ChangeName
    return filename
OSError: [Errno 5] Input/output error
Internal Server Error: /options/260/
Traceback (most recent call last):
  File "/usr/local/lib/python3.5/dist-packages/django/core/handlers/base.py", line 149, in get_response
    response = self.process_exception_by_middleware(e, request)
  File "/usr/local/lib/python3.5/dist-packages/django/core/handlers/base.py", line 147, in get_response
    response = wrapped_callback(request, *callback_args, **callback_kwargs)
  File "/opt/WebWord2Vec/WV/views.py", line 251, in Enteroptions
    args['templates']=Templates.objects.all()
  File "/opt/WebWord2Vec/WV/views.py", line 246, in Map
    return render_to_response('WordMap.html', Map(os.path.join(MEDIA_ROOT,str(xls)),
  File "/opt/WebWord2Vec/WV/views.py", line 218, in BuildHtmlMap
    options.script=script
OSError: [Errno 5] Input/output error
Internal Server Error: /options/314/
Traceback (most recent call last):
  File "/usr/local/lib/python3.5/dist-packages/django/core/handlers/base.py", line 149, in get_response
    response = self.process_exception_by_middleware(e, request)
  File "/usr/local/lib/python3.5/dist-packages/django/core/handlers/base.py", line 147, in get_response
    response = wrapped_callback(request, *callback_args, **callback_kwargs)
  File "/opt/WebWord2Vec/WV/views.py", line 251, in Enteroptions
    args['templates']=Templates.objects.all()
  File "/opt/WebWord2Vec/WV/views.py", line 246, in Map
    return render_to_response('WordMap.html', Map(os.path.join(MEDIA_ROOT,str(xls)),
  File "/opt/WebWord2Vec/WV/views.py", line 218, in BuildHtmlMap
    options.script=script
OSError: [Errno 5] Input/output error
Internal Server Error: /downloadedtexts/1/
Traceback (most recent call last):
  File "/usr/local/lib/python3.5/dist-packages/django/core/handlers/base.py", line 149, in get_response
    response = self.process_exception_by_middleware(e, request)
  File "/usr/local/lib/python3.5/dist-packages/django/core/handlers/base.py", line 147, in get_response
    response = wrapped_callback(request, *callback_args, **callback_kwargs)
  File "/opt/WebWord2Vec/WV/views.py", line 282, in DownloadedTexts
    args['error'] = TagsForm
OSError: [Errno 5] Input/output error
Internal Server Error: /downloadedtexts/1/
Traceback (most recent call last):
  File "/usr/local/lib/python3.5/dist-packages/django/core/handlers/base.py", line 149, in get_response
    response = self.process_exception_by_middleware(e, request)
  File "/usr/local/lib/python3.5/dist-packages/django/core/handlers/base.py", line 147, in get_response
    response = wrapped_callback(request, *callback_args, **callback_kwargs)
  File "/opt/WebWord2Vec/WV/views.py", line 282, in DownloadedTexts
    args['error'] = TagsForm
OSError: [Errno 5] Input/output error
Internal Server Error: /downloadedtexts/1/
Traceback (most recent call last):
  File "/usr/local/lib/python3.5/dist-packages/django/core/handlers/base.py", line 149, in get_response
    response = self.process_exception_by_middleware(e, request)
  File "/usr/local/lib/python3.5/dist-packages/django/core/handlers/base.py", line 147, in get_response
    response = wrapped_callback(request, *callback_args, **callback_kwargs)
  File "/opt/WebWord2Vec/WV/views.py", line 282, in DownloadedTexts
    args['error'] = TagsForm
OSError: [Errno 5] Input/output error
Internal Server Error: /downloadedtexts/1/
Traceback (most recent call last):
  File "/usr/local/lib/python3.5/dist-packages/django/core/handlers/base.py", line 149, in get_response
    response = self.process_exception_by_middleware(e, request)
  File "/usr/local/lib/python3.5/dist-packages/django/core/handlers/base.py", line 147, in get_response
    response = wrapped_callback(request, *callback_args, **callback_kwargs)
  File "/opt/WebWord2Vec/WV/views.py", line 282, in DownloadedTexts
    args['error'] = TagsForm
OSError: [Errno 5] Input/output error
Internal Server Error: /downloadedtexts/1/
Traceback (most recent call last):
  File "/usr/local/lib/python3.5/dist-packages/django/core/handlers/base.py", line 149, in get_response
    response = self.process_exception_by_middleware(e, request)
  File "/usr/local/lib/python3.5/dist-packages/django/core/handlers/base.py", line 147, in get_response
    response = wrapped_callback(request, *callback_args, **callback_kwargs)
  File "/opt/WebWord2Vec/WV/views.py", line 282, in DownloadedTexts
    args['error'] = TagsForm
OSError: [Errno 5] Input/output error
Internal Server Error: /downloadedtexts/1/
Traceback (most recent call last):
  File "/usr/local/lib/python3.5/dist-packages/django/core/handlers/base.py", line 149, in get_response
    response = self.process_exception_by_middleware(e, request)
  File "/usr/local/lib/python3.5/dist-packages/django/core/handlers/base.py", line 147, in get_response
    response = wrapped_callback(request, *callback_args, **callback_kwargs)
  File "/opt/WebWord2Vec/WV/views.py", line 282, in DownloadedTexts
    args['error'] = TagsForm
OSError: [Errno 5] Input/output error
Internal Server Error: /downloadedtexts/1/
Traceback (most recent call last):
  File "/usr/local/lib/python3.5/dist-packages/django/core/handlers/base.py", line 149, in get_response
    response = self.process_exception_by_middleware(e, request)
  File "/usr/local/lib/python3.5/dist-packages/django/core/handlers/base.py", line 147, in get_response
    response = wrapped_callback(request, *callback_args, **callback_kwargs)
  File "/opt/WebWord2Vec/WV/views.py", line 282, in DownloadedTexts
    args['error'] = TagsForm
OSError: [Errno 5] Input/output error
Internal Server Error: /downloadedtexts/1/
Traceback (most recent call last):
  File "/usr/local/lib/python3.5/dist-packages/django/core/handlers/base.py", line 149, in get_response
    response = self.process_exception_by_middleware(e, request)
  File "/usr/local/lib/python3.5/dist-packages/django/core/handlers/base.py", line 147, in get_response
    response = wrapped_callback(request, *callback_args, **callback_kwargs)
  File "/opt/WebWord2Vec/WV/views.py", line 282, in DownloadedTexts
    args['error'] = TagsForm
OSError: [Errno 5] Input/output error
Internal Server Error: /downloadedtexts/1/
Traceback (most recent call last):
  File "/usr/local/lib/python3.5/dist-packages/django/core/handlers/base.py", line 149, in get_response
    response = self.process_exception_by_middleware(e, request)
  File "/usr/local/lib/python3.5/dist-packages/django/core/handlers/base.py", line 147, in get_response
    response = wrapped_callback(request, *callback_args, **callback_kwargs)
  File "/opt/WebWord2Vec/WV/views.py", line 282, in DownloadedTexts
    args['error'] = TagsForm
OSError: [Errno 5] Input/output error
Internal Server Error: /downloadedtexts/1/
Traceback (most recent call last):
  File "/usr/local/lib/python3.5/dist-packages/django/core/handlers/base.py", line 149, in get_response
    response = self.process_exception_by_middleware(e, request)
  File "/usr/local/lib/python3.5/dist-packages/django/core/handlers/base.py", line 147, in get_response
    response = wrapped_callback(request, *callback_args, **callback_kwargs)
  File "/opt/WebWord2Vec/WV/views.py", line 282, in DownloadedTexts
    args['error'] = TagsForm
OSError: [Errno 5] Input/output error
Internal Server Error: /options/314/
Traceback (most recent call last):
  File "/usr/local/lib/python3.5/dist-packages/django/core/handlers/base.py", line 149, in get_response
    response = self.process_exception_by_middleware(e, request)
  File "/usr/local/lib/python3.5/dist-packages/django/core/handlers/base.py", line 147, in get_response
    response = wrapped_callback(request, *callback_args, **callback_kwargs)
  File "/opt/WebWord2Vec/WV/views.py", line 251, in Enteroptions
    args['templates']=Templates.objects.all()
  File "/opt/WebWord2Vec/WV/views.py", line 246, in Map
    return render_to_response('WordMap.html', Map(os.path.join(MEDIA_ROOT,str(xls)),
  File "/opt/WebWord2Vec/WV/views.py", line 218, in BuildHtmlMap
    options.script = script
OSError: [Errno 5] Input/output error
Internal Server Error: /options/314/
Traceback (most recent call last):
  File "/usr/local/lib/python3.5/dist-packages/django/core/handlers/base.py", line 149, in get_response
    response = self.process_exception_by_middleware(e, request)
  File "/usr/local/lib/python3.5/dist-packages/django/core/handlers/base.py", line 147, in get_response
    response = wrapped_callback(request, *callback_args, **callback_kwargs)
  File "/opt/WebWord2Vec/WV/views.py", line 251, in Enteroptions
    args['templates']=Templates.objects.all()
  File "/opt/WebWord2Vec/WV/views.py", line 246, in Map
    return render_to_response('WordMap.html', Map(os.path.join(MEDIA_ROOT,str(xls)),
  File "/opt/WebWord2Vec/WV/views.py", line 218, in BuildHtmlMap
    options.script = script
OSError: [Errno 5] Input/output error
Internal Server Error: /options/314/
Traceback (most recent call last):
  File "/usr/local/lib/python3.5/dist-packages/django/core/handlers/base.py", line 149, in get_response
    response = self.process_exception_by_middleware(e, request)
  File "/usr/local/lib/python3.5/dist-packages/django/core/handlers/base.py", line 147, in get_response
    response = wrapped_callback(request, *callback_args, **callback_kwargs)
  File "/opt/WebWord2Vec/WV/views.py", line 251, in Enteroptions
    args['templates']=Templates.objects.all()
  File "/opt/WebWord2Vec/WV/views.py", line 246, in Map
    return render_to_response('WordMap.html', Map(os.path.join(MEDIA_ROOT,str(xls)),
  File "/opt/WebWord2Vec/WV/views.py", line 218, in BuildHtmlMap
    options.script = script
OSError: [Errno 5] Input/output error
Internal Server Error: /options/314/
Traceback (most recent call last):
  File "/usr/local/lib/python3.5/dist-packages/django/core/handlers/base.py", line 149, in get_response
    response = self.process_exception_by_middleware(e, request)
  File "/usr/local/lib/python3.5/dist-packages/django/core/handlers/base.py", line 147, in get_response
    response = wrapped_callback(request, *callback_args, **callback_kwargs)
  File "/opt/WebWord2Vec/WV/views.py", line 251, in Enteroptions
    args['templates']=Templates.objects.all()
  File "/opt/WebWord2Vec/WV/views.py", line 246, in Map
    return render_to_response('WordMap.html', Map(os.path.join(MEDIA_ROOT,str(xls)),
  File "/opt/WebWord2Vec/WV/views.py", line 218, in BuildHtmlMap
    options.script = script
OSError: [Errno 5] Input/output error
Internal Server Error: /
Traceback (most recent call last):
  File "/usr/local/lib/python3.5/dist-packages/django/core/handlers/base.py", line 149, in get_response
    response = self.process_exception_by_middleware(e, request)
  File "/usr/local/lib/python3.5/dist-packages/django/core/handlers/base.py", line 147, in get_response
    response = wrapped_callback(request, *callback_args, **callback_kwargs)
  File "/opt/WebWord2Vec/WV/views.py", line 51, in MainPage
    if  form_text.is_valid() and form_tg.is_valid() :
  File "/opt/WebWord2Vec/WV/forms.py", line 40, in is_valid
    # we're done now if not valid
  File "/usr/local/lib/python3.5/dist-packages/django/forms/forms.py", line 161, in is_valid
    return self.is_bound and not self.errors
  File "/usr/local/lib/python3.5/dist-packages/django/forms/forms.py", line 153, in errors
    self.full_clean()
  File "/usr/local/lib/python3.5/dist-packages/django/forms/forms.py", line 363, in full_clean
    self._clean_form()
  File "/usr/local/lib/python3.5/dist-packages/django/forms/forms.py", line 390, in _clean_form
    cleaned_data = self.clean()
  File "/opt/WebWord2Vec/WV/forms.py", line 34, in clean
  File "/opt/WebWord2Vec/WV/forms.py", line 31, in ChangeName
    return filename
OSError: [Errno 5] Input/output error
Internal Server Error: /
Traceback (most recent call last):
  File "/usr/local/lib/python3.5/dist-packages/django/core/handlers/base.py", line 149, in get_response
    response = self.process_exception_by_middleware(e, request)
  File "/usr/local/lib/python3.5/dist-packages/django/core/handlers/base.py", line 147, in get_response
    response = wrapped_callback(request, *callback_args, **callback_kwargs)
  File "/opt/WebWord2Vec/WV/views.py", line 51, in MainPage
    if  form_text.is_valid() and form_tg.is_valid() :
  File "/opt/WebWord2Vec/WV/forms.py", line 40, in is_valid
    # we're done now if not valid
  File "/usr/local/lib/python3.5/dist-packages/django/forms/forms.py", line 161, in is_valid
    return self.is_bound and not self.errors
  File "/usr/local/lib/python3.5/dist-packages/django/forms/forms.py", line 153, in errors
    self.full_clean()
  File "/usr/local/lib/python3.5/dist-packages/django/forms/forms.py", line 363, in full_clean
    self._clean_form()
  File "/usr/local/lib/python3.5/dist-packages/django/forms/forms.py", line 390, in _clean_form
    cleaned_data = self.clean()
  File "/opt/WebWord2Vec/WV/forms.py", line 34, in clean
  File "/opt/WebWord2Vec/WV/forms.py", line 31, in ChangeName
    return filename
OSError: [Errno 5] Input/output error
Internal Server Error: /
Traceback (most recent call last):
  File "/usr/local/lib/python3.5/dist-packages/django/core/handlers/base.py", line 149, in get_response
    response = self.process_exception_by_middleware(e, request)
  File "/usr/local/lib/python3.5/dist-packages/django/core/handlers/base.py", line 147, in get_response
    response = wrapped_callback(request, *callback_args, **callback_kwargs)
  File "/opt/WebWord2Vec/WV/views.py", line 51, in MainPage
    if  form_text.is_valid() and form_tg.is_valid() :
  File "/opt/WebWord2Vec/WV/forms.py", line 40, in is_valid
    # we're done now if not valid
  File "/usr/local/lib/python3.5/dist-packages/django/forms/forms.py", line 161, in is_valid
    return self.is_bound and not self.errors
  File "/usr/local/lib/python3.5/dist-packages/django/forms/forms.py", line 153, in errors
    self.full_clean()
  File "/usr/local/lib/python3.5/dist-packages/django/forms/forms.py", line 363, in full_clean
    self._clean_form()
  File "/usr/local/lib/python3.5/dist-packages/django/forms/forms.py", line 390, in _clean_form
    cleaned_data = self.clean()
  File "/opt/WebWord2Vec/WV/forms.py", line 34, in clean
  File "/opt/WebWord2Vec/WV/forms.py", line 31, in ChangeName
    return filename
OSError: [Errno 5] Input/output error
Internal Server Error: /downloadedtexts/1/
Traceback (most recent call last):
  File "/usr/local/lib/python3.5/dist-packages/django/core/handlers/base.py", line 149, in get_response
    response = self.process_exception_by_middleware(e, request)
  File "/usr/local/lib/python3.5/dist-packages/django/core/handlers/base.py", line 147, in get_response
    response = wrapped_callback(request, *callback_args, **callback_kwargs)
  File "/opt/WebWord2Vec/WV/views.py", line 282, in DownloadedTexts
    args['error'] = TagsForm
OSError: [Errno 5] Input/output error
Internal Server Error: /downloadedtexts/1/
Traceback (most recent call last):
  File "/usr/local/lib/python3.5/dist-packages/django/core/handlers/base.py", line 149, in get_response
    response = self.process_exception_by_middleware(e, request)
  File "/usr/local/lib/python3.5/dist-packages/django/core/handlers/base.py", line 147, in get_response
    response = wrapped_callback(request, *callback_args, **callback_kwargs)
  File "/opt/WebWord2Vec/WV/views.py", line 282, in DownloadedTexts
    args['error'] = TagsForm
OSError: [Errno 5] Input/output error
Internal Server Error: /downloadedtexts/1/
Traceback (most recent call last):
  File "/usr/local/lib/python3.5/dist-packages/django/core/handlers/base.py", line 149, in get_response
    response = self.process_exception_by_middleware(e, request)
  File "/usr/local/lib/python3.5/dist-packages/django/core/handlers/base.py", line 147, in get_response
    response = wrapped_callback(request, *callback_args, **callback_kwargs)
  File "/opt/WebWord2Vec/WV/views.py", line 282, in DownloadedTexts
    args['error'] = TagsForm
OSError: [Errno 5] Input/output error
Internal Server Error: /downloadedtexts/1/
Traceback (most recent call last):
  File "/usr/local/lib/python3.5/dist-packages/django/core/handlers/base.py", line 149, in get_response
    response = self.process_exception_by_middleware(e, request)
  File "/usr/local/lib/python3.5/dist-packages/django/core/handlers/base.py", line 147, in get_response
    response = wrapped_callback(request, *callback_args, **callback_kwargs)
  File "/opt/WebWord2Vec/WV/views.py", line 282, in DownloadedTexts
    args['error'] = TagsForm
OSError: [Errno 5] Input/output error
Internal Server Error: /downloadedtexts/1/
Traceback (most recent call last):
  File "/usr/local/lib/python3.5/dist-packages/django/core/handlers/base.py", line 149, in get_response
    response = self.process_exception_by_middleware(e, request)
  File "/usr/local/lib/python3.5/dist-packages/django/core/handlers/base.py", line 147, in get_response
    response = wrapped_callback(request, *callback_args, **callback_kwargs)
  File "/opt/WebWord2Vec/WV/views.py", line 282, in DownloadedTexts
    args['error'] = TagsForm
OSError: [Errno 5] Input/output error
Internal Server Error: /downloadedtexts/1/
Traceback (most recent call last):
  File "/usr/local/lib/python3.5/dist-packages/django/core/handlers/base.py", line 149, in get_response
    response = self.process_exception_by_middleware(e, request)
  File "/usr/local/lib/python3.5/dist-packages/django/core/handlers/base.py", line 147, in get_response
    response = wrapped_callback(request, *callback_args, **callback_kwargs)
  File "/opt/WebWord2Vec/WV/views.py", line 282, in DownloadedTexts
    args['error'] = TagsForm
OSError: [Errno 5] Input/output error
Internal Server Error: /options/314/
Traceback (most recent call last):
  File "/usr/local/lib/python3.5/dist-packages/django/core/handlers/base.py", line 149, in get_response
    response = self.process_exception_by_middleware(e, request)
  File "/usr/local/lib/python3.5/dist-packages/django/core/handlers/base.py", line 147, in get_response
    response = wrapped_callback(request, *callback_args, **callback_kwargs)
  File "/opt/WebWord2Vec/WV/views.py", line 251, in Enteroptions
    args['templates']=Templates.objects.all()
  File "/opt/WebWord2Vec/WV/views.py", line 246, in Map
    return render_to_response('WordMap.html', Map(os.path.join(MEDIA_ROOT,str(xls)),
  File "/opt/WebWord2Vec/WV/views.py", line 218, in BuildHtmlMap
    options.script = script
OSError: [Errno 5] Input/output error
Internal Server Error: /options/314/
Traceback (most recent call last):
  File "/usr/local/lib/python3.5/dist-packages/django/core/handlers/base.py", line 149, in get_response
    response = self.process_exception_by_middleware(e, request)
  File "/usr/local/lib/python3.5/dist-packages/django/core/handlers/base.py", line 147, in get_response
    response = wrapped_callback(request, *callback_args, **callback_kwargs)
  File "/opt/WebWord2Vec/WV/views.py", line 251, in Enteroptions
    args['templates']=Templates.objects.all()
  File "/opt/WebWord2Vec/WV/views.py", line 246, in Map
    return render_to_response('WordMap.html', Map(os.path.join(MEDIA_ROOT,str(xls)),
  File "/opt/WebWord2Vec/WV/views.py", line 218, in BuildHtmlMap
    options.script = script
OSError: [Errno 5] Input/output error
Internal Server Error: /options/314/
Traceback (most recent call last):
  File "/usr/local/lib/python3.5/dist-packages/django/core/handlers/base.py", line 149, in get_response
    response = self.process_exception_by_middleware(e, request)
  File "/usr/local/lib/python3.5/dist-packages/django/core/handlers/base.py", line 147, in get_response
    response = wrapped_callback(request, *callback_args, **callback_kwargs)
  File "/opt/WebWord2Vec/WV/views.py", line 251, in Enteroptions
    args['templates']=Templates.objects.all()
  File "/opt/WebWord2Vec/WV/views.py", line 246, in Map
    return render_to_response('WordMap.html', Map(os.path.join(MEDIA_ROOT,str(xls)),
  File "/opt/WebWord2Vec/WV/views.py", line 218, in BuildHtmlMap
    options.script = script
OSError: [Errno 5] Input/output error
Internal Server Error: /downloadedtexts/1/
Traceback (most recent call last):
  File "/usr/local/lib/python3.5/dist-packages/django/core/handlers/base.py", line 149, in get_response
    response = self.process_exception_by_middleware(e, request)
  File "/usr/local/lib/python3.5/dist-packages/django/core/handlers/base.py", line 147, in get_response
    response = wrapped_callback(request, *callback_args, **callback_kwargs)
  File "/opt/WebWord2Vec/WV/views.py", line 282, in DownloadedTexts
    args['error'] = TagsForm
OSError: [Errno 5] Input/output error
Internal Server Error: /options/315/
Traceback (most recent call last):
  File "/usr/local/lib/python3.5/dist-packages/django/core/handlers/base.py", line 149, in get_response
    response = self.process_exception_by_middleware(e, request)
  File "/usr/local/lib/python3.5/dist-packages/django/core/handlers/base.py", line 147, in get_response
    response = wrapped_callback(request, *callback_args, **callback_kwargs)
  File "/opt/WebWord2Vec/WV/views.py", line 251, in Enteroptions
    args['templates']=Templates.objects.all()
  File "/opt/WebWord2Vec/WV/views.py", line 246, in Map
    return render_to_response('WordMap.html', Map(os.path.join(MEDIA_ROOT,str(xls)),
  File "/opt/WebWord2Vec/WV/views.py", line 218, in BuildHtmlMap
    options.script = script
OSError: [Errno 5] Input/output error
Internal Server Error: /filteredtexts/1/eee/
Traceback (most recent call last):
  File "/usr/local/lib/python3.5/dist-packages/django/core/handlers/base.py", line 149, in get_response
    response = self.process_exception_by_middleware(e, request)
  File "/usr/local/lib/python3.5/dist-packages/django/core/handlers/base.py", line 147, in get_response
    response = wrapped_callback(request, *callback_args, **callback_kwargs)
  File "/opt/WebWord2Vec/WV/views.py", line 320, in FilteredTexts
    args['texts'] = Paginator(all_texts, 10).page(page_number)
OSError: [Errno 5] Input/output error
Internal Server Error: /downloadedtexts/1/
Traceback (most recent call last):
  File "/usr/local/lib/python3.5/dist-packages/django/core/handlers/base.py", line 149, in get_response
    response = self.process_exception_by_middleware(e, request)
  File "/usr/local/lib/python3.5/dist-packages/django/core/handlers/base.py", line 147, in get_response
    response = wrapped_callback(request, *callback_args, **callback_kwargs)
  File "/opt/WebWord2Vec/WV/views.py", line 282, in DownloadedTexts
    args['error'] = TagsForm
OSError: [Errno 5] Input/output error
Internal Server Error: /downloadedtexts/1/
Traceback (most recent call last):
  File "/usr/local/lib/python3.5/dist-packages/django/core/handlers/base.py", line 149, in get_response
    response = self.process_exception_by_middleware(e, request)
  File "/usr/local/lib/python3.5/dist-packages/django/core/handlers/base.py", line 147, in get_response
    response = wrapped_callback(request, *callback_args, **callback_kwargs)
  File "/opt/WebWord2Vec/WV/views.py", line 282, in DownloadedTexts
    args['error'] = TagsForm
OSError: [Errno 5] Input/output error
Internal Server Error: /
Traceback (most recent call last):
  File "/usr/local/lib/python3.5/dist-packages/django/core/handlers/base.py", line 149, in get_response
    response = self.process_exception_by_middleware(e, request)
  File "/usr/local/lib/python3.5/dist-packages/django/core/handlers/base.py", line 147, in get_response
    response = wrapped_callback(request, *callback_args, **callback_kwargs)
  File "/opt/WebWord2Vec/WV/views.py", line 51, in MainPage
    if  form_text.is_valid() and form_tg.is_valid() :
  File "/opt/WebWord2Vec/WV/forms.py", line 40, in is_valid
    # we're done now if not valid
  File "/usr/local/lib/python3.5/dist-packages/django/forms/forms.py", line 161, in is_valid
    return self.is_bound and not self.errors
  File "/usr/local/lib/python3.5/dist-packages/django/forms/forms.py", line 153, in errors
    self.full_clean()
  File "/usr/local/lib/python3.5/dist-packages/django/forms/forms.py", line 363, in full_clean
    self._clean_form()
  File "/usr/local/lib/python3.5/dist-packages/django/forms/forms.py", line 390, in _clean_form
    cleaned_data = self.clean()
  File "/opt/WebWord2Vec/WV/forms.py", line 34, in clean
  File "/opt/WebWord2Vec/WV/forms.py", line 31, in ChangeName
    return filename
OSError: [Errno 5] Input/output error
Internal Server Error: /options/316/
Traceback (most recent call last):
  File "/usr/local/lib/python3.5/dist-packages/django/core/handlers/base.py", line 149, in get_response
    response = self.process_exception_by_middleware(e, request)
  File "/usr/local/lib/python3.5/dist-packages/django/core/handlers/base.py", line 147, in get_response
    response = wrapped_callback(request, *callback_args, **callback_kwargs)
  File "/opt/WebWord2Vec/WV/views.py", line 251, in Enteroptions
    args['templates']=Templates.objects.all()
  File "/opt/WebWord2Vec/WV/views.py", line 246, in Map
    return render_to_response('WordMap.html', Map(os.path.join(MEDIA_ROOT,str(xls)),
  File "/opt/WebWord2Vec/WV/views.py", line 218, in BuildHtmlMap
    options.script = script
OSError: [Errno 5] Input/output error
Internal Server Error: /downloadedtexts/1/
Traceback (most recent call last):
  File "/usr/local/lib/python3.5/dist-packages/django/core/handlers/base.py", line 149, in get_response
    response = self.process_exception_by_middleware(e, request)
  File "/usr/local/lib/python3.5/dist-packages/django/core/handlers/base.py", line 147, in get_response
    response = wrapped_callback(request, *callback_args, **callback_kwargs)
  File "/opt/WebWord2Vec/WV/views.py", line 282, in DownloadedTexts
    args['error'] = TagsForm
OSError: [Errno 5] Input/output error
Internal Server Error: /options/317/
Traceback (most recent call last):
  File "/usr/local/lib/python3.5/dist-packages/django/core/handlers/base.py", line 149, in get_response
    response = self.process_exception_by_middleware(e, request)
  File "/usr/local/lib/python3.5/dist-packages/django/core/handlers/base.py", line 147, in get_response
    response = wrapped_callback(request, *callback_args, **callback_kwargs)
  File "/opt/WebWord2Vec/WV/views.py", line 251, in Enteroptions
    args['form'] = EnterOptions
  File "/opt/WebWord2Vec/WV/views.py", line 246, in Map
    return args
  File "/opt/WebWord2Vec/WV/views.py", line 218, in BuildHtmlMap
OSError: [Errno 5] Input/output error
